Workbook

Sheet Tabulated calculation
A1: Input data | C1: Using NORTRIP wear parameters | E1: Percentage of sand in PMco non-exhaust | P1: Parameters NORTRIP | R1: Scaling coarse sand fraction
A2: Studded tyre fraction | C2: Days since start of studded tyre season | E2: 1 | F2: 5 | G2: 10 | H2: 30 | I2: 50 | J2: 70 | K2: 90 | L2: 110 | M2: 130 | N2: 150 | P2: a | Q2: =(Parameters_NORTRIP!D101-Parameters_NORTRIP!E101)*$R$2 -> 0.003 | R2: 1
A3: 0 | C3: Accumulated traffic (1000 veh.) | E3: =E2*$A$5/1000 -> 22 | F3: =F2*$A$5/1000 -> 110 | G3: =G2*$A$5/1000 -> 220 | H3: =H2*$A$5/1000 -> 660 | I3: =I2*$A$5/1000 -> 1100 | J3: =J2*$A$5/1000 -> 1540 | K3: =K2*$A$5/1000 -> 1980 | L3: =L2*$A$5/1000 -> 2420 | ... N3: =N2*$A$5/1000 -> 3300 | P3: b1 | Q3: =(1-$A$11/100)*(Parameters_NORTRIP!$D$98-Parameters_NORTRIP!$E$98)*(Parameters_NORTRIP!$B$7*$A$19*$A$17/Parameters_NORTRIP!$E$9) -> 0.46315008
A4: ADT | C4: Number of sanding applications | D4: Accumulated sand (kg/m2) | P4: b2 | Q4: =(1-$A$11/100)*(Parameters_NORTRIP!$D$98-Parameters_NORTRIP!$E$98)*(Parameters_NORTRIP!$C$7*$A$19*$A$17/Parameters_NORTRIP!$E$9) -> 0.011578752
A5: 22000 | C5: 1 | D5: =C5*$A$15/1000 -> 0.25 | E5: =($D5)*1000*$Q$2*$A$7*$A$9*1000/(($Q$3*$A$3+$Q$4*(1-$A$3)+$Q$5+$Q$6)*E$3*1000+($D5)*1000*$Q$2*$A$7*$A$9*1000+$A$13*$A$7*$A$9*1000)*100 -> 83.508687 | F5: =($D5)*1000*$Q$2*$A$7*$A$9*1000/(($Q$3*$A$3+$Q$4*(1-$A$3)+$Q$5+$Q$6)*F$3*1000+($D5)*1000*$Q$2*$A$7*$A$9*1000+$A$13*$A$7*$A$9*1000)*100 -> 68.772589 | G5: =($D5)*1000*$Q$2*$A$7*$A$9*1000/(($Q$3*$A$3+$Q$4*(1-$A$3)+$Q$5+$Q$6)*G$3*1000+($D5)*1000*$Q$2*$A$7*$A$9*1000+$A$13*$A$7*$A$9*1000)*100 -> 56.344312 | H5: =($D5)*1000*$Q$2*$A$7*$A$9*1000/(($Q$3*$A$3+$Q$4*(1-$A$3)+$Q$5+$Q$6)*H$3*1000+($D5)*1000*$Q$2*$A$7*$A$9*1000+$A$13*$A$7*$A$9*1000)*100 -> 32.703898 | I5: =($D5)*1000*$Q$2*$A$7*$A$9*1000/(($Q$3*$A$3+$Q$4*(1-$A$3)+$Q$5+$Q$6)*I$3*1000+($D5)*1000*$Q$2*$A$7*$A$9*1000+$A$13*$A$7*$A$9*1000)*100 -> 23.037882 | J5: =($D5)*1000*$Q$2*$A$7*$A$9*1000/(($Q$3*$A$3+$Q$4*(1-$A$3)+$Q$5+$Q$6)*J$3*1000+($D5)*1000*$Q$2*$A$7*$A$9*1000+$A$13*$A$7*$A$9*1000)*100 -> 17.782158 | K5: =($D5)*1000*$Q$2*$A$7*$A$9*1000/(($Q$3*$A$3+$Q$4*(1-$A$3)+$Q$5+$Q$6)*K$3*1000+($D5)*1000*$Q$2*$A$7*$A$9*1000+$A$13*$A$7*$A$9*1000)*100 -> 14.479005 | L5: =($D5)*1000*$Q$2*$A$7*$A$9*1000/(($Q$3*$A$3+$Q$4*(1-$A$3)+$Q$5+$Q$6)*L$3*1000+($D5)*1000*$Q$2*$A$7*$A$9*1000+$A$13*$A$7*$A$9*1000)*100 -> 12.210774 | ... N5: =($D5)*1000*$Q$2*$A$7*$A$9*1000/(($Q$3*$A$3+$Q$4*(1-$A$3)+$Q$5+$Q$6)*N$3*1000+($D5)*1000*$Q$2*$A$7*$A$9*1000+$A$13*$A$7*$A$9*1000)*100 -> 9.2976863 | P5: b3 | Q5: =($A$11/100)*(Parameters_NORTRIP!$D$98-Parameters_NORTRIP!$E$98)*(Parameters_NORTRIP!$C$6) -> 0.0046368
A6: Lane width | C6: 2 | D6: =C6*$A$15/1000 -> 0.5 | E6: =($D6)*1000*$Q$2*$A$7*$A$9*1000/(($Q$3*$A$3+$Q$4*(1-$A$3)+$Q$5+$Q$6)*E$3*1000+($D6)*1000*$Q$2*$A$7*$A$9*1000+$A$13*$A$7*$A$9*1000)*100 -> 91.013334 | F6: =($D6)*1000*$Q$2*$A$7*$A$9*1000/(($Q$3*$A$3+$Q$4*(1-$A$3)+$Q$5+$Q$6)*F$3*1000+($D6)*1000*$Q$2*$A$7*$A$9*1000+$A$13*$A$7*$A$9*1000)*100 -> 81.497345 | G6: =($D6)*1000*$Q$2*$A$7*$A$9*1000/(($Q$3*$A$3+$Q$4*(1-$A$3)+$Q$5+$Q$6)*G$3*1000+($D6)*1000*$Q$2*$A$7*$A$9*1000+$A$13*$A$7*$A$9*1000)*100 -> 72.077214 | H6: =($D6)*1000*$Q$2*$A$7*$A$9*1000/(($Q$3*$A$3+$Q$4*(1-$A$3)+$Q$5+$Q$6)*H$3*1000+($D6)*1000*$Q$2*$A$7*$A$9*1000+$A$13*$A$7*$A$9*1000)*100 -> 49.288527 | I6: =($D6)*1000*$Q$2*$A$7*$A$9*1000/(($Q$3*$A$3+$Q$4*(1-$A$3)+$Q$5+$Q$6)*I$3*1000+($D6)*1000*$Q$2*$A$7*$A$9*1000+$A$13*$A$7*$A$9*1000)*100 -> 37.448437 | J6: =($D6)*1000*$Q$2*$A$7*$A$9*1000/(($Q$3*$A$3+$Q$4*(1-$A$3)+$Q$5+$Q$6)*J$3*1000+($D6)*1000*$Q$2*$A$7*$A$9*1000+$A$13*$A$7*$A$9*1000)*100 -> 30.194995 | K6: =($D6)*1000*$Q$2*$A$7*$A$9*1000/(($Q$3*$A$3+$Q$4*(1-$A$3)+$Q$5+$Q$6)*K$3*1000+($D6)*1000*$Q$2*$A$7*$A$9*1000+$A$13*$A$7*$A$9*1000)*100 -> 25.295477 | L6: =($D6)*1000*$Q$2*$A$7*$A$9*1000/(($Q$3*$A$3+$Q$4*(1-$A$3)+$Q$5+$Q$6)*L$3*1000+($D6)*1000*$Q$2*$A$7*$A$9*1000+$A$13*$A$7*$A$9*1000)*100 -> 21.763995 | ... N6: =($D6)*1000*$Q$2*$A$7*$A$9*1000/(($Q$3*$A$3+$Q$4*(1-$A$3)+$Q$5+$Q$6)*N$3*1000+($D6)*1000*$Q$2*$A$7*$A$9*1000+$A$13*$A$7*$A$9*1000)*100 -> 17.01351 | P6: c | Q6: =(Parameters_NORTRIP!$D$99-Parameters_NORTRIP!$E$99)*((1-$A$11/100)*Parameters_NORTRIP!$B$13+($A$11/100)*Parameters_NORTRIP!$B$12)+(Parameters_NORTRIP!$D$100-Parameters_NORTRIP!$E$100)*((1-$A$11/100)*Parameters_NORTRIP!$B$19*Parameters_NORTRIP!$C$41+($A$11/100)*Parameters_NORTRIP!$B$18*Parameters_NORTRIP!$C$41) -> 0.0144
A7: 3.5 | C7: 4 | D7: =C7*$A$15/1000 -> 1 | E7: =($D7)*1000*$Q$2*$A$7*$A$9*1000/(($Q$3*$A$3+$Q$4*(1-$A$3)+$Q$5+$Q$6)*E$3*1000+($D7)*1000*$Q$2*$A$7*$A$9*1000+$A$13*$A$7*$A$9*1000)*100 -> 95.295268 | F7: =($D7)*1000*$Q$2*$A$7*$A$9*1000/(($Q$3*$A$3+$Q$4*(1-$A$3)+$Q$5+$Q$6)*F$3*1000+($D7)*1000*$Q$2*$A$7*$A$9*1000+$A$13*$A$7*$A$9*1000)*100 -> 89.80555 | G7: =($D7)*1000*$Q$2*$A$7*$A$9*1000/(($Q$3*$A$3+$Q$4*(1-$A$3)+$Q$5+$Q$6)*G$3*1000+($D7)*1000*$Q$2*$A$7*$A$9*1000+$A$13*$A$7*$A$9*1000)*100 -> 83.773107 | H7: =($D7)*1000*$Q$2*$A$7*$A$9*1000/(($Q$3*$A$3+$Q$4*(1-$A$3)+$Q$5+$Q$6)*H$3*1000+($D7)*1000*$Q$2*$A$7*$A$9*1000+$A$13*$A$7*$A$9*1000)*100 -> 66.031232 | I7: =($D7)*1000*$Q$2*$A$7*$A$9*1000/(($Q$3*$A$3+$Q$4*(1-$A$3)+$Q$5+$Q$6)*I$3*1000+($D7)*1000*$Q$2*$A$7*$A$9*1000+$A$13*$A$7*$A$9*1000)*100 -> 54.490888 | J7: =($D7)*1000*$Q$2*$A$7*$A$9*1000/(($Q$3*$A$3+$Q$4*(1-$A$3)+$Q$5+$Q$6)*J$3*1000+($D7)*1000*$Q$2*$A$7*$A$9*1000+$A$13*$A$7*$A$9*1000)*100 -> 46.384264 | K7: =($D7)*1000*$Q$2*$A$7*$A$9*1000/(($Q$3*$A$3+$Q$4*(1-$A$3)+$Q$5+$Q$6)*K$3*1000+($D7)*1000*$Q$2*$A$7*$A$9*1000+$A$13*$A$7*$A$9*1000)*100 -> 40.377319 | L7: =($D7)*1000*$Q$2*$A$7*$A$9*1000/(($Q$3*$A$3+$Q$4*(1-$A$3)+$Q$5+$Q$6)*L$3*1000+($D7)*1000*$Q$2*$A$7*$A$9*1000+$A$13*$A$7*$A$9*1000)*100 -> 35.747834 | ... N7: =($D7)*1000*$Q$2*$A$7*$A$9*1000/(($Q$3*$A$3+$Q$4*(1-$A$3)+$Q$5+$Q$6)*N$3*1000+($D7)*1000*$Q$2*$A$7*$A$9*1000+$A$13*$A$7*$A$9*1000)*100 -> 29.079565
A8: Number of lanes | C8: 6 | D8: =C8*$A$15/1000 -> 1.5 | E8: =($D8)*1000*$Q$2*$A$7*$A$9*1000/(($Q$3*$A$3+$Q$4*(1-$A$3)+$Q$5+$Q$6)*E$3*1000+($D8)*1000*$Q$2*$A$7*$A$9*1000+$A$13*$A$7*$A$9*1000)*100 -> 96.81354 | F8: =($D8)*1000*$Q$2*$A$7*$A$9*1000/(($Q$3*$A$3+$Q$4*(1-$A$3)+$Q$5+$Q$6)*F$3*1000+($D8)*1000*$Q$2*$A$7*$A$9*1000+$A$13*$A$7*$A$9*1000)*100 -> 92.964628 | G8: =($D8)*1000*$Q$2*$A$7*$A$9*1000/(($Q$3*$A$3+$Q$4*(1-$A$3)+$Q$5+$Q$6)*G$3*1000+($D8)*1000*$Q$2*$A$7*$A$9*1000+$A$13*$A$7*$A$9*1000)*100 -> 88.563473 | H8: =($D8)*1000*$Q$2*$A$7*$A$9*1000/(($Q$3*$A$3+$Q$4*(1-$A$3)+$Q$5+$Q$6)*H$3*1000+($D8)*1000*$Q$2*$A$7*$A$9*1000+$A$13*$A$7*$A$9*1000)*100 -> 74.462571 | I8: =($D8)*1000*$Q$2*$A$7*$A$9*1000/(($Q$3*$A$3+$Q$4*(1-$A$3)+$Q$5+$Q$6)*I$3*1000+($D8)*1000*$Q$2*$A$7*$A$9*1000+$A$13*$A$7*$A$9*1000)*100 -> 64.235174 | J8: =($D8)*1000*$Q$2*$A$7*$A$9*1000/(($Q$3*$A$3+$Q$4*(1-$A$3)+$Q$5+$Q$6)*J$3*1000+($D8)*1000*$Q$2*$A$7*$A$9*1000+$A$13*$A$7*$A$9*1000)*100 -> 56.477954 | K8: =($D8)*1000*$Q$2*$A$7*$A$9*1000/(($Q$3*$A$3+$Q$4*(1-$A$3)+$Q$5+$Q$6)*K$3*1000+($D8)*1000*$Q$2*$A$7*$A$9*1000+$A$13*$A$7*$A$9*1000)*100 -> 50.392424 | L8: =($D8)*1000*$Q$2*$A$7*$A$9*1000/(($Q$3*$A$3+$Q$4*(1-$A$3)+$Q$5+$Q$6)*L$3*1000+($D8)*1000*$Q$2*$A$7*$A$9*1000+$A$13*$A$7*$A$9*1000)*100 -> 45.490769 | ... N8: =($D8)*1000*$Q$2*$A$7*$A$9*1000/(($Q$3*$A$3+$Q$4*(1-$A$3)+$Q$5+$Q$6)*N$3*1000+($D8)*1000*$Q$2*$A$7*$A$9*1000+$A$13*$A$7*$A$9*1000)*100 -> 38.082268
A9: 4 | C9: 8 | D9: =C9*$A$15/1000 -> 2 | E9: =($D9)*1000*$Q$2*$A$7*$A$9*1000/(($Q$3*$A$3+$Q$4*(1-$A$3)+$Q$5+$Q$6)*E$3*1000+($D9)*1000*$Q$2*$A$7*$A$9*1000+$A$13*$A$7*$A$9*1000)*100 -> 97.590965 | F9: =($D9)*1000*$Q$2*$A$7*$A$9*1000/(($Q$3*$A$3+$Q$4*(1-$A$3)+$Q$5+$Q$6)*F$3*1000+($D9)*1000*$Q$2*$A$7*$A$9*1000+$A$13*$A$7*$A$9*1000)*100 -> 94.629003 | G9: =($D9)*1000*$Q$2*$A$7*$A$9*1000/(($Q$3*$A$3+$Q$4*(1-$A$3)+$Q$5+$Q$6)*G$3*1000+($D9)*1000*$Q$2*$A$7*$A$9*1000+$A$13*$A$7*$A$9*1000)*100 -> 91.170148 | H9: =($D9)*1000*$Q$2*$A$7*$A$9*1000/(($Q$3*$A$3+$Q$4*(1-$A$3)+$Q$5+$Q$6)*H$3*1000+($D9)*1000*$Q$2*$A$7*$A$9*1000+$A$13*$A$7*$A$9*1000)*100 -> 79.540736 | I9: =($D9)*1000*$Q$2*$A$7*$A$9*1000/(($Q$3*$A$3+$Q$4*(1-$A$3)+$Q$5+$Q$6)*I$3*1000+($D9)*1000*$Q$2*$A$7*$A$9*1000+$A$13*$A$7*$A$9*1000)*100 -> 70.542527 | J9: =($D9)*1000*$Q$2*$A$7*$A$9*1000/(($Q$3*$A$3+$Q$4*(1-$A$3)+$Q$5+$Q$6)*J$3*1000+($D9)*1000*$Q$2*$A$7*$A$9*1000+$A$13*$A$7*$A$9*1000)*100 -> 63.373292 | K9: =($D9)*1000*$Q$2*$A$7*$A$9*1000/(($Q$3*$A$3+$Q$4*(1-$A$3)+$Q$5+$Q$6)*K$3*1000+($D9)*1000*$Q$2*$A$7*$A$9*1000+$A$13*$A$7*$A$9*1000)*100 -> 57.526842 | L9: =($D9)*1000*$Q$2*$A$7*$A$9*1000/(($Q$3*$A$3+$Q$4*(1-$A$3)+$Q$5+$Q$6)*L$3*1000+($D9)*1000*$Q$2*$A$7*$A$9*1000+$A$13*$A$7*$A$9*1000)*100 -> 52.667999 | ... N9: =($D9)*1000*$Q$2*$A$7*$A$9*1000/(($Q$3*$A$3+$Q$4*(1-$A$3)+$Q$5+$Q$6)*N$3*1000+($D9)*1000*$Q$2*$A$7*$A$9*1000+$A$13*$A$7*$A$9*1000)*100 -> 45.056807
A10: % heavy duty vehicles | C10: 10 | D10: =C10*$A$15/1000 -> 2.5 | E10: =($D10)*1000*$Q$2*$A$7*$A$9*1000/(($Q$3*$A$3+$Q$4*(1-$A$3)+$Q$5+$Q$6)*E$3*1000+($D10)*1000*$Q$2*$A$7*$A$9*1000+$A$13*$A$7*$A$9*1000)*100 -> 98.063441 | F10: =($D10)*1000*$Q$2*$A$7*$A$9*1000/(($Q$3*$A$3+$Q$4*(1-$A$3)+$Q$5+$Q$6)*F$3*1000+($D10)*1000*$Q$2*$A$7*$A$9*1000+$A$13*$A$7*$A$9*1000)*100 -> 95.656545 | G10: =($D10)*1000*$Q$2*$A$7*$A$9*1000/(($Q$3*$A$3+$Q$4*(1-$A$3)+$Q$5+$Q$6)*G$3*1000+($D10)*1000*$Q$2*$A$7*$A$9*1000+$A$13*$A$7*$A$9*1000)*100 -> 92.80913 | H10: =($D10)*1000*$Q$2*$A$7*$A$9*1000/(($Q$3*$A$3+$Q$4*(1-$A$3)+$Q$5+$Q$6)*H$3*1000+($D10)*1000*$Q$2*$A$7*$A$9*1000+$A$13*$A$7*$A$9*1000)*100 -> 82.934285 | I10: =($D10)*1000*$Q$2*$A$7*$A$9*1000/(($Q$3*$A$3+$Q$4*(1-$A$3)+$Q$5+$Q$6)*I$3*1000+($D10)*1000*$Q$2*$A$7*$A$9*1000+$A$13*$A$7*$A$9*1000)*100 -> 74.958715 | J10: =($D10)*1000*$Q$2*$A$7*$A$9*1000/(($Q$3*$A$3+$Q$4*(1-$A$3)+$Q$5+$Q$6)*J$3*1000+($D10)*1000*$Q$2*$A$7*$A$9*1000+$A$13*$A$7*$A$9*1000)*100 -> 68.382548 | K10: =($D10)*1000*$Q$2*$A$7*$A$9*1000/(($Q$3*$A$3+$Q$4*(1-$A$3)+$Q$5+$Q$6)*K$3*1000+($D10)*1000*$Q$2*$A$7*$A$9*1000+$A$13*$A$7*$A$9*1000)*100 -> 62.867177 | L10: =($D10)*1000*$Q$2*$A$7*$A$9*1000/(($Q$3*$A$3+$Q$4*(1-$A$3)+$Q$5+$Q$6)*L$3*1000+($D10)*1000*$Q$2*$A$7*$A$9*1000+$A$13*$A$7*$A$9*1000)*100 -> 58.175086 | ... N10: =($D10)*1000*$Q$2*$A$7*$A$9*1000/(($Q$3*$A$3+$Q$4*(1-$A$3)+$Q$5+$Q$6)*N$3*1000+($D10)*1000*$Q$2*$A$7*$A$9*1000+$A$13*$A$7*$A$9*1000)*100 -> 50.619164
A11: 5 | C11: 15 | D11: =C11*$A$15/1000 -> 3.75 | E11: =($D11)*1000*$Q$2*$A$7*$A$9*1000/(($Q$3*$A$3+$Q$4*(1-$A$3)+$Q$5+$Q$6)*E$3*1000+($D11)*1000*$Q$2*$A$7*$A$9*1000+$A$13*$A$7*$A$9*1000)*100 -> 98.700573 | F11: =($D11)*1000*$Q$2*$A$7*$A$9*1000/(($Q$3*$A$3+$Q$4*(1-$A$3)+$Q$5+$Q$6)*F$3*1000+($D11)*1000*$Q$2*$A$7*$A$9*1000+$A$13*$A$7*$A$9*1000)*100 -> 97.061824 | G11: =($D11)*1000*$Q$2*$A$7*$A$9*1000/(($Q$3*$A$3+$Q$4*(1-$A$3)+$Q$5+$Q$6)*G$3*1000+($D11)*1000*$Q$2*$A$7*$A$9*1000+$A$13*$A$7*$A$9*1000)*100 -> 95.088356 | H11: =($D11)*1000*$Q$2*$A$7*$A$9*1000/(($Q$3*$A$3+$Q$4*(1-$A$3)+$Q$5+$Q$6)*H$3*1000+($D11)*1000*$Q$2*$A$7*$A$9*1000+$A$13*$A$7*$A$9*1000)*100 -> 87.936623 | I11: =($D11)*1000*$Q$2*$A$7*$A$9*1000/(($Q$3*$A$3+$Q$4*(1-$A$3)+$Q$5+$Q$6)*I$3*1000+($D11)*1000*$Q$2*$A$7*$A$9*1000+$A$13*$A$7*$A$9*1000)*100 -> 81.785422 | J11: =($D11)*1000*$Q$2*$A$7*$A$9*1000/(($Q$3*$A$3+$Q$4*(1-$A$3)+$Q$5+$Q$6)*J$3*1000+($D11)*1000*$Q$2*$A$7*$A$9*1000+$A$13*$A$7*$A$9*1000)*100 -> 76.438518 | K11: =($D11)*1000*$Q$2*$A$7*$A$9*1000/(($Q$3*$A$3+$Q$4*(1-$A$3)+$Q$5+$Q$6)*K$3*1000+($D11)*1000*$Q$2*$A$7*$A$9*1000+$A$13*$A$7*$A$9*1000)*100 -> 71.747843 | L11: =($D11)*1000*$Q$2*$A$7*$A$9*1000/(($Q$3*$A$3+$Q$4*(1-$A$3)+$Q$5+$Q$6)*L$3*1000+($D11)*1000*$Q$2*$A$7*$A$9*1000+$A$13*$A$7*$A$9*1000)*100 -> 67.599573 | ... N11: =($D11)*1000*$Q$2*$A$7*$A$9*1000/(($Q$3*$A$3+$Q$4*(1-$A$3)+$Q$5+$Q$6)*N$3*1000+($D11)*1000*$Q$2*$A$7*$A$9*1000+$A$13*$A$7*$A$9*1000)*100 -> 60.592929
A12: Initial mass PMco (g/m2) | C12: 20 | D12: =C12*$A$15/1000 -> 5 | E12: =($D12)*1000*$Q$2*$A$7*$A$9*1000/(($Q$3*$A$3+$Q$4*(1-$A$3)+$Q$5+$Q$6)*E$3*1000+($D12)*1000*$Q$2*$A$7*$A$9*1000+$A$13*$A$7*$A$9*1000)*100 -> 99.022253 | F12: =($D12)*1000*$Q$2*$A$7*$A$9*1000/(($Q$3*$A$3+$Q$4*(1-$A$3)+$Q$5+$Q$6)*F$3*1000+($D12)*1000*$Q$2*$A$7*$A$9*1000+$A$13*$A$7*$A$9*1000)*100 -> 97.780062 | G12: =($D12)*1000*$Q$2*$A$7*$A$9*1000/(($Q$3*$A$3+$Q$4*(1-$A$3)+$Q$5+$Q$6)*G$3*1000+($D12)*1000*$Q$2*$A$7*$A$9*1000+$A$13*$A$7*$A$9*1000)*100 -> 96.270472 | H12: =($D12)*1000*$Q$2*$A$7*$A$9*1000/(($Q$3*$A$3+$Q$4*(1-$A$3)+$Q$5+$Q$6)*H$3*1000+($D12)*1000*$Q$2*$A$7*$A$9*1000+$A$13*$A$7*$A$9*1000)*100 -> 90.671123 | I12: =($D12)*1000*$Q$2*$A$7*$A$9*1000/(($Q$3*$A$3+$Q$4*(1-$A$3)+$Q$5+$Q$6)*I$3*1000+($D12)*1000*$Q$2*$A$7*$A$9*1000+$A$13*$A$7*$A$9*1000)*100 -> 85.687318 | J12: =($D12)*1000*$Q$2*$A$7*$A$9*1000/(($Q$3*$A$3+$Q$4*(1-$A$3)+$Q$5+$Q$6)*J$3*1000+($D12)*1000*$Q$2*$A$7*$A$9*1000+$A$13*$A$7*$A$9*1000)*100 -> 81.222845 | K12: =($D12)*1000*$Q$2*$A$7*$A$9*1000/(($Q$3*$A$3+$Q$4*(1-$A$3)+$Q$5+$Q$6)*K$3*1000+($D12)*1000*$Q$2*$A$7*$A$9*1000+$A$13*$A$7*$A$9*1000)*100 -> 77.200548 | L12: =($D12)*1000*$Q$2*$A$7*$A$9*1000/(($Q$3*$A$3+$Q$4*(1-$A$3)+$Q$5+$Q$6)*L$3*1000+($D12)*1000*$Q$2*$A$7*$A$9*1000+$A$13*$A$7*$A$9*1000)*100 -> 73.557837 | ... N12: =($D12)*1000*$Q$2*$A$7*$A$9*1000/(($Q$3*$A$3+$Q$4*(1-$A$3)+$Q$5+$Q$6)*N$3*1000+($D12)*1000*$Q$2*$A$7*$A$9*1000+$A$13*$A$7*$A$9*1000)*100 -> 67.214772
A13: 0.1 | C13: 25 | D13: =C13*$A$15/1000 -> 6.25 | E13: =($D13)*1000*$Q$2*$A$7*$A$9*1000/(($Q$3*$A$3+$Q$4*(1-$A$3)+$Q$5+$Q$6)*E$3*1000+($D13)*1000*$Q$2*$A$7*$A$9*1000+$A$13*$A$7*$A$9*1000)*100 -> 99.21627 | F13: =($D13)*1000*$Q$2*$A$7*$A$9*1000/(($Q$3*$A$3+$Q$4*(1-$A$3)+$Q$5+$Q$6)*F$3*1000+($D13)*1000*$Q$2*$A$7*$A$9*1000+$A$13*$A$7*$A$9*1000)*100 -> 98.216129 | G13: =($D13)*1000*$Q$2*$A$7*$A$9*1000/(($Q$3*$A$3+$Q$4*(1-$A$3)+$Q$5+$Q$6)*G$3*1000+($D13)*1000*$Q$2*$A$7*$A$9*1000+$A$13*$A$7*$A$9*1000)*100 -> 96.993955 | H13: =($D13)*1000*$Q$2*$A$7*$A$9*1000/(($Q$3*$A$3+$Q$4*(1-$A$3)+$Q$5+$Q$6)*H$3*1000+($D13)*1000*$Q$2*$A$7*$A$9*1000+$A$13*$A$7*$A$9*1000)*100 -> 92.395006 | I13: =($D13)*1000*$Q$2*$A$7*$A$9*1000/(($Q$3*$A$3+$Q$4*(1-$A$3)+$Q$5+$Q$6)*I$3*1000+($D13)*1000*$Q$2*$A$7*$A$9*1000+$A$13*$A$7*$A$9*1000)*100 -> 88.212431 | J13: =($D13)*1000*$Q$2*$A$7*$A$9*1000/(($Q$3*$A$3+$Q$4*(1-$A$3)+$Q$5+$Q$6)*J$3*1000+($D13)*1000*$Q$2*$A$7*$A$9*1000+$A$13*$A$7*$A$9*1000)*100 -> 84.392133 | K13: =($D13)*1000*$Q$2*$A$7*$A$9*1000/(($Q$3*$A$3+$Q$4*(1-$A$3)+$Q$5+$Q$6)*K$3*1000+($D13)*1000*$Q$2*$A$7*$A$9*1000+$A$13*$A$7*$A$9*1000)*100 -> 80.888998 | L13: =($D13)*1000*$Q$2*$A$7*$A$9*1000/(($Q$3*$A$3+$Q$4*(1-$A$3)+$Q$5+$Q$6)*L$3*1000+($D13)*1000*$Q$2*$A$7*$A$9*1000+$A$13*$A$7*$A$9*1000)*100 -> 77.665103 | ... N13: =($D13)*1000*$Q$2*$A$7*$A$9*1000/(($Q$3*$A$3+$Q$4*(1-$A$3)+$Q$5+$Q$6)*N$3*1000+($D13)*1000*$Q$2*$A$7*$A$9*1000+$A$13*$A$7*$A$9*1000)*100 -> 71.931343
A14: Sand dosage (g/m2) | C14: 30 | D14: =C14*$A$15/1000 -> 7.5 | E14: =($D14)*1000*$Q$2*$A$7*$A$9*1000/(($Q$3*$A$3+$Q$4*(1-$A$3)+$Q$5+$Q$6)*E$3*1000+($D14)*1000*$Q$2*$A$7*$A$9*1000+$A$13*$A$7*$A$9*1000)*100 -> 99.346037 | F14: =($D14)*1000*$Q$2*$A$7*$A$9*1000/(($Q$3*$A$3+$Q$4*(1-$A$3)+$Q$5+$Q$6)*F$3*1000+($D14)*1000*$Q$2*$A$7*$A$9*1000+$A$13*$A$7*$A$9*1000)*100 -> 98.509008 | G14: =($D14)*1000*$Q$2*$A$7*$A$9*1000/(($Q$3*$A$3+$Q$4*(1-$A$3)+$Q$5+$Q$6)*G$3*1000+($D14)*1000*$Q$2*$A$7*$A$9*1000+$A$13*$A$7*$A$9*1000)*100 -> 97.482349 | H14: =($D14)*1000*$Q$2*$A$7*$A$9*1000/(($Q$3*$A$3+$Q$4*(1-$A$3)+$Q$5+$Q$6)*H$3*1000+($D14)*1000*$Q$2*$A$7*$A$9*1000+$A$13*$A$7*$A$9*1000)*100 -> 93.581146 | I14: =($D14)*1000*$Q$2*$A$7*$A$9*1000/(($Q$3*$A$3+$Q$4*(1-$A$3)+$Q$5+$Q$6)*I$3*1000+($D14)*1000*$Q$2*$A$7*$A$9*1000+$A$13*$A$7*$A$9*1000)*100 -> 89.980177 | J14: =($D14)*1000*$Q$2*$A$7*$A$9*1000/(($Q$3*$A$3+$Q$4*(1-$A$3)+$Q$5+$Q$6)*J$3*1000+($D14)*1000*$Q$2*$A$7*$A$9*1000+$A$13*$A$7*$A$9*1000)*100 -> 86.646067 | K14: =($D14)*1000*$Q$2*$A$7*$A$9*1000/(($Q$3*$A$3+$Q$4*(1-$A$3)+$Q$5+$Q$6)*K$3*1000+($D14)*1000*$Q$2*$A$7*$A$9*1000+$A$13*$A$7*$A$9*1000)*100 -> 83.550212 | L14: =($D14)*1000*$Q$2*$A$7*$A$9*1000/(($Q$3*$A$3+$Q$4*(1-$A$3)+$Q$5+$Q$6)*L$3*1000+($D14)*1000*$Q$2*$A$7*$A$9*1000+$A$13*$A$7*$A$9*1000)*100 -> 80.667954 | ... N14: =($D14)*1000*$Q$2*$A$7*$A$9*1000/(($Q$3*$A$3+$Q$4*(1-$A$3)+$Q$5+$Q$6)*N$3*1000+($D14)*1000*$Q$2*$A$7*$A$9*1000+$A$13*$A$7*$A$9*1000)*100 -> 75.461515
A15: 250 | C15: 35 | D15: =C15*$A$15/1000 -> 8.75 | E15: =($D15)*1000*$Q$2*$A$7*$A$9*1000/(($Q$3*$A$3+$Q$4*(1-$A$3)+$Q$5+$Q$6)*E$3*1000+($D15)*1000*$Q$2*$A$7*$A$9*1000+$A$13*$A$7*$A$9*1000)*100 -> 99.438937 | F15: =($D15)*1000*$Q$2*$A$7*$A$9*1000/(($Q$3*$A$3+$Q$4*(1-$A$3)+$Q$5+$Q$6)*F$3*1000+($D15)*1000*$Q$2*$A$7*$A$9*1000+$A$13*$A$7*$A$9*1000)*100 -> 98.719279 | G15: =($D15)*1000*$Q$2*$A$7*$A$9*1000/(($Q$3*$A$3+$Q$4*(1-$A$3)+$Q$5+$Q$6)*G$3*1000+($D15)*1000*$Q$2*$A$7*$A$9*1000+$A$13*$A$7*$A$9*1000)*100 -> 97.834224 | H15: =($D15)*1000*$Q$2*$A$7*$A$9*1000/(($Q$3*$A$3+$Q$4*(1-$A$3)+$Q$5+$Q$6)*H$3*1000+($D15)*1000*$Q$2*$A$7*$A$9*1000+$A$13*$A$7*$A$9*1000)*100 -> 94.447207 | I15: =($D15)*1000*$Q$2*$A$7*$A$9*1000/(($Q$3*$A$3+$Q$4*(1-$A$3)+$Q$5+$Q$6)*I$3*1000+($D15)*1000*$Q$2*$A$7*$A$9*1000+$A$13*$A$7*$A$9*1000)*100 -> 91.28686 | J15: =($D15)*1000*$Q$2*$A$7*$A$9*1000/(($Q$3*$A$3+$Q$4*(1-$A$3)+$Q$5+$Q$6)*J$3*1000+($D15)*1000*$Q$2*$A$7*$A$9*1000+$A$13*$A$7*$A$9*1000)*100 -> 88.331165 | K15: =($D15)*1000*$Q$2*$A$7*$A$9*1000/(($Q$3*$A$3+$Q$4*(1-$A$3)+$Q$5+$Q$6)*K$3*1000+($D15)*1000*$Q$2*$A$7*$A$9*1000+$A$13*$A$7*$A$9*1000)*100 -> 85.560866 | L15: =($D15)*1000*$Q$2*$A$7*$A$9*1000/(($Q$3*$A$3+$Q$4*(1-$A$3)+$Q$5+$Q$6)*L$3*1000+($D15)*1000*$Q$2*$A$7*$A$9*1000+$A$13*$A$7*$A$9*1000)*100 -> 82.959051 | ... N15: =($D15)*1000*$Q$2*$A$7*$A$9*1000/(($Q$3*$A$3+$Q$4*(1-$A$3)+$Q$5+$Q$6)*N$3*1000+($D15)*1000*$Q$2*$A$7*$A$9*1000+$A$13*$A$7*$A$9*1000)*100 -> 78.202917
A16: Traffic speed (km/h) | C16: 40 | D16: =C16*$A$15/1000 -> 10 | E16: =($D16)*1000*$Q$2*$A$7*$A$9*1000/(($Q$3*$A$3+$Q$4*(1-$A$3)+$Q$5+$Q$6)*E$3*1000+($D16)*1000*$Q$2*$A$7*$A$9*1000+$A$13*$A$7*$A$9*1000)*100 -> 99.508725 | F16: =($D16)*1000*$Q$2*$A$7*$A$9*1000/(($Q$3*$A$3+$Q$4*(1-$A$3)+$Q$5+$Q$6)*F$3*1000+($D16)*1000*$Q$2*$A$7*$A$9*1000+$A$13*$A$7*$A$9*1000)*100 -> 98.877572 | G16: =($D16)*1000*$Q$2*$A$7*$A$9*1000/(($Q$3*$A$3+$Q$4*(1-$A$3)+$Q$5+$Q$6)*G$3*1000+($D16)*1000*$Q$2*$A$7*$A$9*1000+$A$13*$A$7*$A$9*1000)*100 -> 98.099802 | H16: =($D16)*1000*$Q$2*$A$7*$A$9*1000/(($Q$3*$A$3+$Q$4*(1-$A$3)+$Q$5+$Q$6)*H$3*1000+($D16)*1000*$Q$2*$A$7*$A$9*1000+$A$13*$A$7*$A$9*1000)*100 -> 95.107347 | I16: =($D16)*1000*$Q$2*$A$7*$A$9*1000/(($Q$3*$A$3+$Q$4*(1-$A$3)+$Q$5+$Q$6)*I$3*1000+($D16)*1000*$Q$2*$A$7*$A$9*1000+$A$13*$A$7*$A$9*1000)*100 -> 92.292052 | J16: =($D16)*1000*$Q$2*$A$7*$A$9*1000/(($Q$3*$A$3+$Q$4*(1-$A$3)+$Q$5+$Q$6)*J$3*1000+($D16)*1000*$Q$2*$A$7*$A$9*1000+$A$13*$A$7*$A$9*1000)*100 -> 89.638638 | K16: =($D16)*1000*$Q$2*$A$7*$A$9*1000/(($Q$3*$A$3+$Q$4*(1-$A$3)+$Q$5+$Q$6)*K$3*1000+($D16)*1000*$Q$2*$A$7*$A$9*1000+$A$13*$A$7*$A$9*1000)*100 -> 87.133532 | L16: =($D16)*1000*$Q$2*$A$7*$A$9*1000/(($Q$3*$A$3+$Q$4*(1-$A$3)+$Q$5+$Q$6)*L$3*1000+($D16)*1000*$Q$2*$A$7*$A$9*1000+$A$13*$A$7*$A$9*1000)*100 -> 84.764639 | ... N16: =($D16)*1000*$Q$2*$A$7*$A$9*1000/(($Q$3*$A$3+$Q$4*(1-$A$3)+$Q$5+$Q$6)*N$3*1000+($D16)*1000*$Q$2*$A$7*$A$9*1000+$A$13*$A$7*$A$9*1000)*100 -> 80.393342
A17: 46 | C17: 45 | D17: =C17*$A$15/1000 -> 11.25 | E17: =($D17)*1000*$Q$2*$A$7*$A$9*1000/(($Q$3*$A$3+$Q$4*(1-$A$3)+$Q$5+$Q$6)*E$3*1000+($D17)*1000*$Q$2*$A$7*$A$9*1000+$A$13*$A$7*$A$9*1000)*100 -> 99.563073 | F17: =($D17)*1000*$Q$2*$A$7*$A$9*1000/(($Q$3*$A$3+$Q$4*(1-$A$3)+$Q$5+$Q$6)*F$3*1000+($D17)*1000*$Q$2*$A$7*$A$9*1000+$A$13*$A$7*$A$9*1000)*100 -> 99.001041 | G17: =($D17)*1000*$Q$2*$A$7*$A$9*1000/(($Q$3*$A$3+$Q$4*(1-$A$3)+$Q$5+$Q$6)*G$3*1000+($D17)*1000*$Q$2*$A$7*$A$9*1000+$A$13*$A$7*$A$9*1000)*100 -> 98.307361 | H17: =($D17)*1000*$Q$2*$A$7*$A$9*1000/(($Q$3*$A$3+$Q$4*(1-$A$3)+$Q$5+$Q$6)*H$3*1000+($D17)*1000*$Q$2*$A$7*$A$9*1000+$A$13*$A$7*$A$9*1000)*100 -> 95.627203 | I17: =($D17)*1000*$Q$2*$A$7*$A$9*1000/(($Q$3*$A$3+$Q$4*(1-$A$3)+$Q$5+$Q$6)*I$3*1000+($D17)*1000*$Q$2*$A$7*$A$9*1000+$A$13*$A$7*$A$9*1000)*100 -> 93.089305 | J17: =($D17)*1000*$Q$2*$A$7*$A$9*1000/(($Q$3*$A$3+$Q$4*(1-$A$3)+$Q$5+$Q$6)*J$3*1000+($D17)*1000*$Q$2*$A$7*$A$9*1000+$A$13*$A$7*$A$9*1000)*100 -> 90.682633 | K17: =($D17)*1000*$Q$2*$A$7*$A$9*1000/(($Q$3*$A$3+$Q$4*(1-$A$3)+$Q$5+$Q$6)*K$3*1000+($D17)*1000*$Q$2*$A$7*$A$9*1000+$A$13*$A$7*$A$9*1000)*100 -> 88.397266 | L17: =($D17)*1000*$Q$2*$A$7*$A$9*1000/(($Q$3*$A$3+$Q$4*(1-$A$3)+$Q$5+$Q$6)*L$3*1000+($D17)*1000*$Q$2*$A$7*$A$9*1000+$A$13*$A$7*$A$9*1000)*100 -> 86.224258 | ... N17: =($D17)*1000*$Q$2*$A$7*$A$9*1000/(($Q$3*$A$3+$Q$4*(1-$A$3)+$Q$5+$Q$6)*N$3*1000+($D17)*1000*$Q$2*$A$7*$A$9*1000+$A$13*$A$7*$A$9*1000)*100 -> 82.183729
A18: Road wear scaling (hpave) | C18: 50 | D18: =C18*$A$15/1000 -> 12.5 | E18: =($D18)*1000*$Q$2*$A$7*$A$9*1000/(($Q$3*$A$3+$Q$4*(1-$A$3)+$Q$5+$Q$6)*E$3*1000+($D18)*1000*$Q$2*$A$7*$A$9*1000+$A$13*$A$7*$A$9*1000)*100 -> 99.606593 | F18: =($D18)*1000*$Q$2*$A$7*$A$9*1000/(($Q$3*$A$3+$Q$4*(1-$A$3)+$Q$5+$Q$6)*F$3*1000+($D18)*1000*$Q$2*$A$7*$A$9*1000+$A$13*$A$7*$A$9*1000)*100 -> 99.100038 | G18: =($D18)*1000*$Q$2*$A$7*$A$9*1000/(($Q$3*$A$3+$Q$4*(1-$A$3)+$Q$5+$Q$6)*G$3*1000+($D18)*1000*$Q$2*$A$7*$A$9*1000+$A$13*$A$7*$A$9*1000)*100 -> 98.474042 | H18: =($D18)*1000*$Q$2*$A$7*$A$9*1000/(($Q$3*$A$3+$Q$4*(1-$A$3)+$Q$5+$Q$6)*H$3*1000+($D18)*1000*$Q$2*$A$7*$A$9*1000+$A$13*$A$7*$A$9*1000)*100 -> 96.047198 | I18: =($D18)*1000*$Q$2*$A$7*$A$9*1000/(($Q$3*$A$3+$Q$4*(1-$A$3)+$Q$5+$Q$6)*I$3*1000+($D18)*1000*$Q$2*$A$7*$A$9*1000+$A$13*$A$7*$A$9*1000)*100 -> 93.737093 | J18: =($D18)*1000*$Q$2*$A$7*$A$9*1000/(($Q$3*$A$3+$Q$4*(1-$A$3)+$Q$5+$Q$6)*J$3*1000+($D18)*1000*$Q$2*$A$7*$A$9*1000+$A$13*$A$7*$A$9*1000)*100 -> 91.535503 | K18: =($D18)*1000*$Q$2*$A$7*$A$9*1000/(($Q$3*$A$3+$Q$4*(1-$A$3)+$Q$5+$Q$6)*K$3*1000+($D18)*1000*$Q$2*$A$7*$A$9*1000+$A$13*$A$7*$A$9*1000)*100 -> 89.434956 | L18: =($D18)*1000*$Q$2*$A$7*$A$9*1000/(($Q$3*$A$3+$Q$4*(1-$A$3)+$Q$5+$Q$6)*L$3*1000+($D18)*1000*$Q$2*$A$7*$A$9*1000+$A$13*$A$7*$A$9*1000)*100 -> 87.428653 | ... N18: =($D18)*1000*$Q$2*$A$7*$A$9*1000/(($Q$3*$A$3+$Q$4*(1-$A$3)+$Q$5+$Q$6)*N$3*1000+($D18)*1000*$Q$2*$A$7*$A$9*1000+$A$13*$A$7*$A$9*1000)*100 -> 83.674497
A19: 1 | C19: 55 | D19: =C19*$A$15/1000 -> 13.75 | E19: =($D19)*1000*$Q$2*$A$7*$A$9*1000/(($Q$3*$A$3+$Q$4*(1-$A$3)+$Q$5+$Q$6)*E$3*1000+($D19)*1000*$Q$2*$A$7*$A$9*1000+$A$13*$A$7*$A$9*1000)*100 -> 99.64223 | F19: =($D19)*1000*$Q$2*$A$7*$A$9*1000/(($Q$3*$A$3+$Q$4*(1-$A$3)+$Q$5+$Q$6)*F$3*1000+($D19)*1000*$Q$2*$A$7*$A$9*1000+$A$13*$A$7*$A$9*1000)*100 -> 99.181182 | G19: =($D19)*1000*$Q$2*$A$7*$A$9*1000/(($Q$3*$A$3+$Q$4*(1-$A$3)+$Q$5+$Q$6)*G$3*1000+($D19)*1000*$Q$2*$A$7*$A$9*1000+$A$13*$A$7*$A$9*1000)*100 -> 98.610839 | H19: =($D19)*1000*$Q$2*$A$7*$A$9*1000/(($Q$3*$A$3+$Q$4*(1-$A$3)+$Q$5+$Q$6)*H$3*1000+($D19)*1000*$Q$2*$A$7*$A$9*1000+$A$13*$A$7*$A$9*1000)*100 -> 96.393584 | I19: =($D19)*1000*$Q$2*$A$7*$A$9*1000/(($Q$3*$A$3+$Q$4*(1-$A$3)+$Q$5+$Q$6)*I$3*1000+($D19)*1000*$Q$2*$A$7*$A$9*1000+$A$13*$A$7*$A$9*1000)*100 -> 94.273846 | J19: =($D19)*1000*$Q$2*$A$7*$A$9*1000/(($Q$3*$A$3+$Q$4*(1-$A$3)+$Q$5+$Q$6)*J$3*1000+($D19)*1000*$Q$2*$A$7*$A$9*1000+$A$13*$A$7*$A$9*1000)*100 -> 92.24533 | K19: =($D19)*1000*$Q$2*$A$7*$A$9*1000/(($Q$3*$A$3+$Q$4*(1-$A$3)+$Q$5+$Q$6)*K$3*1000+($D19)*1000*$Q$2*$A$7*$A$9*1000+$A$13*$A$7*$A$9*1000)*100 -> 90.302272 | L19: =($D19)*1000*$Q$2*$A$7*$A$9*1000/(($Q$3*$A$3+$Q$4*(1-$A$3)+$Q$5+$Q$6)*L$3*1000+($D19)*1000*$Q$2*$A$7*$A$9*1000+$A$13*$A$7*$A$9*1000)*100 -> 88.439382 | ... N19: =($D19)*1000*$Q$2*$A$7*$A$9*1000/(($Q$3*$A$3+$Q$4*(1-$A$3)+$Q$5+$Q$6)*N$3*1000+($D19)*1000*$Q$2*$A$7*$A$9*1000+$A$13*$A$7*$A$9*1000)*100 -> 84.935049
A24: Input data | C24: Using EMEP/EEA wear parameters | E24: Percentage of sand in PMco non-exhaust | P24: Parameters EMEP/EEA | R24: Scaling coarse sand fraction
A25: Studded tyre fraction | C25: Days since start of studded tyre season | E25: 1 | F25: 5 | G25: 10 | H25: 30 | I25: 50 | J25: 70 | K25: 90 | L25: 110 | M25: 130 | N25: 150 | P25: a | Q25: =('Parameters_EMEP-EEA'!D101-'Parameters_EMEP-EEA'!E101)*$R$25 -> 0.003 | R25: 1
A26: 0 | C26: Accumulated traffic (1000 veh.) | E26: =E25*$A$5/1000 -> 22 | F26: =F25*$A$5/1000 -> 110 | G26: =G25*$A$5/1000 -> 220 | H26: =H25*$A$5/1000 -> 660 | I26: =I25*$A$5/1000 -> 1100 | J26: =J25*$A$5/1000 -> 1540 | K26: =K25*$A$5/1000 -> 1980 | L26: =L25*$A$5/1000 -> 2420 | ... N26: =N25*$A$5/1000 -> 3300 | P26: b1 | Q26: =(1-$A$34/100)*('Parameters_EMEP-EEA'!$D$98-'Parameters_EMEP-EEA'!$E$98)*('Parameters_EMEP-EEA'!$B$7*$A$42*$A$40/'Parameters_EMEP-EEA'!$E$9) -> 0.41352686
A27: ADT | C27: Number of sanding applications | D27: Accumulated sand (kg/m2) | P27: b2 | Q27: =(1-$A$34/100)*('Parameters_EMEP-EEA'!$D$98-'Parameters_EMEP-EEA'!$E$98)*('Parameters_EMEP-EEA'!$C$7*$A$42*$A$40/'Parameters_EMEP-EEA'!$E$9) -> 0.0021537857
A28: 22000 | C28: 1 | D28: =C28*$A$15/1000 -> 0.25 | E28: =($D28)*1000*$Q$25*$A$30*$A$32*1000/(($Q$26*$A$26+$Q$27*(1-$A$26)+$Q$28+$Q$29)*E$26*1000+($D28)*1000*$Q$25*$A$30*$A$32*1000+$A$36*$A$30*$A$32*1000)*100 -> 86.57194 | F28: =($D28)*1000*$Q$25*$A$30*$A$32*1000/(($Q$26*$A$26+$Q$27*(1-$A$26)+$Q$28+$Q$29)*F$26*1000+($D28)*1000*$Q$25*$A$30*$A$32*1000+$A$36*$A$30*$A$32*1000)*100 -> 80.501678 | G28: =($D28)*1000*$Q$25*$A$30*$A$32*1000/(($Q$26*$A$26+$Q$27*(1-$A$26)+$Q$28+$Q$29)*G$26*1000+($D28)*1000*$Q$25*$A$30*$A$32*1000+$A$36*$A$30*$A$32*1000)*100 -> 74.014482 | H28: =($D28)*1000*$Q$25*$A$30*$A$32*1000/(($Q$26*$A$26+$Q$27*(1-$A$26)+$Q$28+$Q$29)*H$26*1000+($D28)*1000*$Q$25*$A$30*$A$32*1000+$A$36*$A$30*$A$32*1000)*100 -> 55.972421 | I28: =($D28)*1000*$Q$25*$A$30*$A$32*1000/(($Q$26*$A$26+$Q$27*(1-$A$26)+$Q$28+$Q$29)*I$26*1000+($D28)*1000*$Q$25*$A$30*$A$32*1000+$A$36*$A$30*$A$32*1000)*100 -> 45.002448 | J28: =($D28)*1000*$Q$25*$A$30*$A$32*1000/(($Q$26*$A$26+$Q$27*(1-$A$26)+$Q$28+$Q$29)*J$26*1000+($D28)*1000*$Q$25*$A$30*$A$32*1000+$A$36*$A$30*$A$32*1000)*100 -> 37.627814 | K28: =($D28)*1000*$Q$25*$A$30*$A$32*1000/(($Q$26*$A$26+$Q$27*(1-$A$26)+$Q$28+$Q$29)*K$26*1000+($D28)*1000*$Q$25*$A$30*$A$32*1000+$A$36*$A$30*$A$32*1000)*100 -> 32.32986 | L28: =($D28)*1000*$Q$25*$A$30*$A$32*1000/(($Q$26*$A$26+$Q$27*(1-$A$26)+$Q$28+$Q$29)*L$26*1000+($D28)*1000*$Q$25*$A$30*$A$32*1000+$A$36*$A$30*$A$32*1000)*100 -> 28.339667 | ... N28: =($D28)*1000*$Q$25*$A$30*$A$32*1000/(($Q$26*$A$26+$Q$27*(1-$A$26)+$Q$28+$Q$29)*N$26*1000+($D28)*1000*$Q$25*$A$30*$A$32*1000+$A$36*$A$30*$A$32*1000)*100 -> 22.729146 | P28: b3 | Q28: =($A$34/100)*('Parameters_EMEP-EEA'!$D$98-'Parameters_EMEP-EEA'!$E$98)*('Parameters_EMEP-EEA'!$C$6) -> 0.000874
A29: Lane width | C29: 2 | D29: =C29*$A$15/1000 -> 0.5 | E29: =($D29)*1000*$Q$25*$A$30*$A$32*1000/(($Q$26*$A$26+$Q$27*(1-$A$26)+$Q$28+$Q$29)*E$26*1000+($D29)*1000*$Q$25*$A$30*$A$32*1000+$A$36*$A$30*$A$32*1000)*100 -> 92.802744 | F29: =($D29)*1000*$Q$25*$A$30*$A$32*1000/(($Q$26*$A$26+$Q$27*(1-$A$26)+$Q$28+$Q$29)*F$26*1000+($D29)*1000*$Q$25*$A$30*$A$32*1000+$A$36*$A$30*$A$32*1000)*100 -> 89.197706 | G29: =($D29)*1000*$Q$25*$A$30*$A$32*1000/(($Q$26*$A$26+$Q$27*(1-$A$26)+$Q$28+$Q$29)*G$26*1000+($D29)*1000*$Q$25*$A$30*$A$32*1000+$A$36*$A$30*$A$32*1000)*100 -> 85.067037 | H29: =($D29)*1000*$Q$25*$A$30*$A$32*1000/(($Q$26*$A$26+$Q$27*(1-$A$26)+$Q$28+$Q$29)*H$26*1000+($D29)*1000*$Q$25*$A$30*$A$32*1000+$A$36*$A$30*$A$32*1000)*100 -> 71.772203 | I29: =($D29)*1000*$Q$25*$A$30*$A$32*1000/(($Q$26*$A$26+$Q$27*(1-$A$26)+$Q$28+$Q$29)*I$26*1000+($D29)*1000*$Q$25*$A$30*$A$32*1000+$A$36*$A$30*$A$32*1000)*100 -> 62.071294 | J29: =($D29)*1000*$Q$25*$A$30*$A$32*1000/(($Q$26*$A$26+$Q$27*(1-$A$26)+$Q$28+$Q$29)*J$26*1000+($D29)*1000*$Q$25*$A$30*$A$32*1000+$A$36*$A$30*$A$32*1000)*100 -> 54.680537 | K29: =($D29)*1000*$Q$25*$A$30*$A$32*1000/(($Q$26*$A$26+$Q$27*(1-$A$26)+$Q$28+$Q$29)*K$26*1000+($D29)*1000*$Q$25*$A$30*$A$32*1000+$A$36*$A$30*$A$32*1000)*100 -> 48.862532 | L29: =($D29)*1000*$Q$25*$A$30*$A$32*1000/(($Q$26*$A$26+$Q$27*(1-$A$26)+$Q$28+$Q$29)*L$26*1000+($D29)*1000*$Q$25*$A$30*$A$32*1000+$A$36*$A$30*$A$32*1000)*100 -> 44.163535 | ... N29: =($D29)*1000*$Q$25*$A$30*$A$32*1000/(($Q$26*$A$26+$Q$27*(1-$A$26)+$Q$28+$Q$29)*N$26*1000+($D29)*1000*$Q$25*$A$30*$A$32*1000+$A$36*$A$30*$A$32*1000)*100 -> 37.039524 | P29: c | Q29: =('Parameters_EMEP-EEA'!$D$99-'Parameters_EMEP-EEA'!$E$99)*((1-$A$34/100)*'Parameters_EMEP-EEA'!$B$13+($A$34/100)*'Parameters_EMEP-EEA'!$B$12)+('Parameters_EMEP-EEA'!$D$100-'Parameters_EMEP-EEA'!$E$100)*((1-$A$34/100)*'Parameters_EMEP-EEA'!$B$19*'Parameters_EMEP-EEA'!$C$41+($A$34/100)*'Parameters_EMEP-EEA'!$B$18*'Parameters_EMEP-EEA'!$C$41) -> 0.007365
A30: 3.5 | C30: 4 | D30: =C30*$A$15/1000 -> 1 | E30: =($D30)*1000*$Q$25*$A$30*$A$32*1000/(($Q$26*$A$26+$Q$27*(1-$A$26)+$Q$28+$Q$29)*E$26*1000+($D30)*1000*$Q$25*$A$30*$A$32*1000+$A$36*$A$30*$A$32*1000)*100 -> 96.267036 | F30: =($D30)*1000*$Q$25*$A$30*$A$32*1000/(($Q$26*$A$26+$Q$27*(1-$A$26)+$Q$28+$Q$29)*F$26*1000+($D30)*1000*$Q$25*$A$30*$A$32*1000+$A$36*$A$30*$A$32*1000)*100 -> 94.290473 | G30: =($D30)*1000*$Q$25*$A$30*$A$32*1000/(($Q$26*$A$26+$Q$27*(1-$A$26)+$Q$28+$Q$29)*G$26*1000+($D30)*1000*$Q$25*$A$30*$A$32*1000+$A$36*$A$30*$A$32*1000)*100 -> 91.931052 | H30: =($D30)*1000*$Q$25*$A$30*$A$32*1000/(($Q$26*$A$26+$Q$27*(1-$A$26)+$Q$28+$Q$29)*H$26*1000+($D30)*1000*$Q$25*$A$30*$A$32*1000+$A$36*$A$30*$A$32*1000)*100 -> 83.566726 | I30: =($D30)*1000*$Q$25*$A$30*$A$32*1000/(($Q$26*$A$26+$Q$27*(1-$A$26)+$Q$28+$Q$29)*I$26*1000+($D30)*1000*$Q$25*$A$30*$A$32*1000+$A$36*$A$30*$A$32*1000)*100 -> 76.597517 | J30: =($D30)*1000*$Q$25*$A$30*$A$32*1000/(($Q$26*$A$26+$Q$27*(1-$A$26)+$Q$28+$Q$29)*J$26*1000+($D30)*1000*$Q$25*$A$30*$A$32*1000+$A$36*$A$30*$A$32*1000)*100 -> 70.70125 | K30: =($D30)*1000*$Q$25*$A$30*$A$32*1000/(($Q$26*$A$26+$Q$27*(1-$A$26)+$Q$28+$Q$29)*K$26*1000+($D30)*1000*$Q$25*$A$30*$A$32*1000+$A$36*$A$30*$A$32*1000)*100 -> 65.647858 | L30: =($D30)*1000*$Q$25*$A$30*$A$32*1000/(($Q$26*$A$26+$Q$27*(1-$A$26)+$Q$28+$Q$29)*L$26*1000+($D30)*1000*$Q$25*$A$30*$A$32*1000+$A$36*$A$30*$A$32*1000)*100 -> 61.268663 | ... N30: =($D30)*1000*$Q$25*$A$30*$A$32*1000/(($Q$26*$A$26+$Q$27*(1-$A$26)+$Q$28+$Q$29)*N$26*1000+($D30)*1000*$Q$25*$A$30*$A$32*1000+$A$36*$A$30*$A$32*1000)*100 -> 54.056703
A31: Number of lanes | C31: 6 | D31: =C31*$A$15/1000 -> 1.5 | E31: =($D31)*1000*$Q$25*$A$30*$A$32*1000/(($Q$26*$A$26+$Q$27*(1-$A$26)+$Q$28+$Q$29)*E$26*1000+($D31)*1000*$Q$25*$A$30*$A$32*1000+$A$36*$A$30*$A$32*1000)*100 -> 97.480001 | F31: =($D31)*1000*$Q$25*$A$30*$A$32*1000/(($Q$26*$A$26+$Q$27*(1-$A$26)+$Q$28+$Q$29)*F$26*1000+($D31)*1000*$Q$25*$A$30*$A$32*1000+$A$36*$A$30*$A$32*1000)*100 -> 96.119802 | G31: =($D31)*1000*$Q$25*$A$30*$A$32*1000/(($Q$26*$A$26+$Q$27*(1-$A$26)+$Q$28+$Q$29)*G$26*1000+($D31)*1000*$Q$25*$A$30*$A$32*1000+$A$36*$A$30*$A$32*1000)*100 -> 94.472018 | H31: =($D31)*1000*$Q$25*$A$30*$A$32*1000/(($Q$26*$A$26+$Q$27*(1-$A$26)+$Q$28+$Q$29)*H$26*1000+($D31)*1000*$Q$25*$A$30*$A$32*1000+$A$36*$A$30*$A$32*1000)*100 -> 88.409589 | I31: =($D31)*1000*$Q$25*$A$30*$A$32*1000/(($Q$26*$A$26+$Q$27*(1-$A$26)+$Q$28+$Q$29)*I$26*1000+($D31)*1000*$Q$25*$A$30*$A$32*1000+$A$36*$A$30*$A$32*1000)*100 -> 83.078313 | J31: =($D31)*1000*$Q$25*$A$30*$A$32*1000/(($Q$26*$A$26+$Q$27*(1-$A$26)+$Q$28+$Q$29)*J$26*1000+($D31)*1000*$Q$25*$A$30*$A$32*1000+$A$36*$A$30*$A$32*1000)*100 -> 78.353443 | K31: =($D31)*1000*$Q$25*$A$30*$A$32*1000/(($Q$26*$A$26+$Q$27*(1-$A$26)+$Q$28+$Q$29)*K$26*1000+($D31)*1000*$Q$25*$A$30*$A$32*1000+$A$36*$A$30*$A$32*1000)*100 -> 74.137083 | L31: =($D31)*1000*$Q$25*$A$30*$A$32*1000/(($Q$26*$A$26+$Q$27*(1-$A$26)+$Q$28+$Q$29)*L$26*1000+($D31)*1000*$Q$25*$A$30*$A$32*1000+$A$36*$A$30*$A$32*1000)*100 -> 70.351333 | ... N31: =($D31)*1000*$Q$25*$A$30*$A$32*1000/(($Q$26*$A$26+$Q$27*(1-$A$26)+$Q$28+$Q$29)*N$26*1000+($D31)*1000*$Q$25*$A$30*$A$32*1000+$A$36*$A$30*$A$32*1000)*100 -> 63.832249
A32: 4 | C32: 8 | D32: =C32*$A$15/1000 -> 2 | E32: =($D32)*1000*$Q$25*$A$30*$A$32*1000/(($Q$26*$A$26+$Q$27*(1-$A$26)+$Q$28+$Q$29)*E$26*1000+($D32)*1000*$Q$25*$A$30*$A$32*1000+$A$36*$A$30*$A$32*1000)*100 -> 98.098018 | F32: =($D32)*1000*$Q$25*$A$30*$A$32*1000/(($Q$26*$A$26+$Q$27*(1-$A$26)+$Q$28+$Q$29)*F$26*1000+($D32)*1000*$Q$25*$A$30*$A$32*1000+$A$36*$A$30*$A$32*1000)*100 -> 97.061345 | G32: =($D32)*1000*$Q$25*$A$30*$A$32*1000/(($Q$26*$A$26+$Q$27*(1-$A$26)+$Q$28+$Q$29)*G$26*1000+($D32)*1000*$Q$25*$A$30*$A$32*1000+$A$36*$A$30*$A$32*1000)*100 -> 95.795913 | H32: =($D32)*1000*$Q$25*$A$30*$A$32*1000/(($Q$26*$A$26+$Q$27*(1-$A$26)+$Q$28+$Q$29)*H$26*1000+($D32)*1000*$Q$25*$A$30*$A$32*1000+$A$36*$A$30*$A$32*1000)*100 -> 91.047792 | I32: =($D32)*1000*$Q$25*$A$30*$A$32*1000/(($Q$26*$A$26+$Q$27*(1-$A$26)+$Q$28+$Q$29)*I$26*1000+($D32)*1000*$Q$25*$A$30*$A$32*1000+$A$36*$A$30*$A$32*1000)*100 -> 86.748125 | J32: =($D32)*1000*$Q$25*$A$30*$A$32*1000/(($Q$26*$A$26+$Q$27*(1-$A$26)+$Q$28+$Q$29)*J$26*1000+($D32)*1000*$Q$25*$A$30*$A$32*1000+$A$36*$A$30*$A$32*1000)*100 -> 82.836242 | K32: =($D32)*1000*$Q$25*$A$30*$A$32*1000/(($Q$26*$A$26+$Q$27*(1-$A$26)+$Q$28+$Q$29)*K$26*1000+($D32)*1000*$Q$25*$A$30*$A$32*1000+$A$36*$A$30*$A$32*1000)*100 -> 79.261946 | L32: =($D32)*1000*$Q$25*$A$30*$A$32*1000/(($Q$26*$A$26+$Q$27*(1-$A$26)+$Q$28+$Q$29)*L$26*1000+($D32)*1000*$Q$25*$A$30*$A$32*1000+$A$36*$A$30*$A$32*1000)*100 -> 75.983346 | ... N32: =($D32)*1000*$Q$25*$A$30*$A$32*1000/(($Q$26*$A$26+$Q$27*(1-$A$26)+$Q$28+$Q$29)*N$26*1000+($D32)*1000*$Q$25*$A$30*$A$32*1000+$A$36*$A$30*$A$32*1000)*100 -> 70.177671
A33: % heavy duty vehicles | C33: 10 | D33: =C33*$A$15/1000 -> 2.5 | E33: =($D33)*1000*$Q$25*$A$30*$A$32*1000/(($Q$26*$A$26+$Q$27*(1-$A$26)+$Q$28+$Q$29)*E$26*1000+($D33)*1000*$Q$25*$A$30*$A$32*1000+$A$36*$A$30*$A$32*1000)*100 -> 98.472604 | F33: =($D33)*1000*$Q$25*$A$30*$A$32*1000/(($Q$26*$A$26+$Q$27*(1-$A$26)+$Q$28+$Q$29)*F$26*1000+($D33)*1000*$Q$25*$A$30*$A$32*1000+$A$36*$A$30*$A$32*1000)*100 -> 97.635177 | G33: =($D33)*1000*$Q$25*$A$30*$A$32*1000/(($Q$26*$A$26+$Q$27*(1-$A$26)+$Q$28+$Q$29)*G$26*1000+($D33)*1000*$Q$25*$A$30*$A$32*1000+$A$36*$A$30*$A$32*1000)*100 -> 96.608212 | H33: =($D33)*1000*$Q$25*$A$30*$A$32*1000/(($Q$26*$A$26+$Q$27*(1-$A$26)+$Q$28+$Q$29)*H$26*1000+($D33)*1000*$Q$25*$A$30*$A$32*1000+$A$36*$A$30*$A$32*1000)*100 -> 92.707669 | I33: =($D33)*1000*$Q$25*$A$30*$A$32*1000/(($Q$26*$A$26+$Q$27*(1-$A$26)+$Q$28+$Q$29)*I$26*1000+($D33)*1000*$Q$25*$A$30*$A$32*1000+$A$36*$A$30*$A$32*1000)*100 -> 89.109871 | J33: =($D33)*1000*$Q$25*$A$30*$A$32*1000/(($Q$26*$A$26+$Q$27*(1-$A$26)+$Q$28+$Q$29)*J$26*1000+($D33)*1000*$Q$25*$A$30*$A$32*1000+$A$36*$A$30*$A$32*1000)*100 -> 85.780887 | K33: =($D33)*1000*$Q$25*$A$30*$A$32*1000/(($Q$26*$A$26+$Q$27*(1-$A$26)+$Q$28+$Q$29)*K$26*1000+($D33)*1000*$Q$25*$A$30*$A$32*1000+$A$36*$A$30*$A$32*1000)*100 -> 82.691675 | L33: =($D33)*1000*$Q$25*$A$30*$A$32*1000/(($Q$26*$A$26+$Q$27*(1-$A$26)+$Q$28+$Q$29)*L$26*1000+($D33)*1000*$Q$25*$A$30*$A$32*1000+$A$36*$A$30*$A$32*1000)*100 -> 79.817231 | ... N33: =($D33)*1000*$Q$25*$A$30*$A$32*1000/(($Q$26*$A$26+$Q$27*(1-$A$26)+$Q$28+$Q$29)*N$26*1000+($D33)*1000*$Q$25*$A$30*$A$32*1000+$A$36*$A$30*$A$32*1000)*100 -> 74.628885
A34: 5 | C34: 15 | D34: =C34*$A$15/1000 -> 3.75 | E34: =($D34)*1000*$Q$25*$A$30*$A$32*1000/(($Q$26*$A$26+$Q$27*(1-$A$26)+$Q$28+$Q$29)*E$26*1000+($D34)*1000*$Q$25*$A$30*$A$32*1000+$A$36*$A$30*$A$32*1000)*100 -> 98.976525 | F34: =($D34)*1000*$Q$25*$A$30*$A$32*1000/(($Q$26*$A$26+$Q$27*(1-$A$26)+$Q$28+$Q$29)*F$26*1000+($D34)*1000*$Q$25*$A$30*$A$32*1000+$A$36*$A$30*$A$32*1000)*100 -> 98.410925 | G34: =($D34)*1000*$Q$25*$A$30*$A$32*1000/(($Q$26*$A$26+$Q$27*(1-$A$26)+$Q$28+$Q$29)*G$26*1000+($D34)*1000*$Q$25*$A$30*$A$32*1000+$A$36*$A$30*$A$32*1000)*100 -> 97.712951 | H34: =($D34)*1000*$Q$25*$A$30*$A$32*1000/(($Q$26*$A$26+$Q$27*(1-$A$26)+$Q$28+$Q$29)*H$26*1000+($D34)*1000*$Q$25*$A$30*$A$32*1000+$A$36*$A$30*$A$32*1000)*100 -> 95.017328 | I34: =($D34)*1000*$Q$25*$A$30*$A$32*1000/(($Q$26*$A$26+$Q$27*(1-$A$26)+$Q$28+$Q$29)*I$26*1000+($D34)*1000*$Q$25*$A$30*$A$32*1000+$A$36*$A$30*$A$32*1000)*100 -> 92.466442 | J34: =($D34)*1000*$Q$25*$A$30*$A$32*1000/(($Q$26*$A$26+$Q$27*(1-$A$26)+$Q$28+$Q$29)*J$26*1000+($D34)*1000*$Q$25*$A$30*$A$32*1000+$A$36*$A$30*$A$32*1000)*100 -> 90.04894 | K34: =($D34)*1000*$Q$25*$A$30*$A$32*1000/(($Q$26*$A$26+$Q$27*(1-$A$26)+$Q$28+$Q$29)*K$26*1000+($D34)*1000*$Q$25*$A$30*$A$32*1000+$A$36*$A$30*$A$32*1000)*100 -> 87.754627 | L34: =($D34)*1000*$Q$25*$A$30*$A$32*1000/(($Q$26*$A$26+$Q$27*(1-$A$26)+$Q$28+$Q$29)*L$26*1000+($D34)*1000*$Q$25*$A$30*$A$32*1000+$A$36*$A$30*$A$32*1000)*100 -> 85.57432 | ... N34: =($D34)*1000*$Q$25*$A$30*$A$32*1000/(($Q$26*$A$26+$Q$27*(1-$A$26)+$Q$28+$Q$29)*N$26*1000+($D34)*1000*$Q$25*$A$30*$A$32*1000+$A$36*$A$30*$A$32*1000)*100 -> 81.523346
A35: Initial mass PMco (g/m2) | C35: 20 | D35: =C35*$A$15/1000 -> 5 | E35: =($D35)*1000*$Q$25*$A$30*$A$32*1000/(($Q$26*$A$26+$Q$27*(1-$A$26)+$Q$28+$Q$29)*E$26*1000+($D35)*1000*$Q$25*$A$30*$A$32*1000+$A$36*$A$30*$A$32*1000)*100 -> 99.230425 | F35: =($D35)*1000*$Q$25*$A$30*$A$32*1000/(($Q$26*$A$26+$Q$27*(1-$A$26)+$Q$28+$Q$29)*F$26*1000+($D35)*1000*$Q$25*$A$30*$A$32*1000+$A$36*$A$30*$A$32*1000)*100 -> 98.80344 | G35: =($D35)*1000*$Q$25*$A$30*$A$32*1000/(($Q$26*$A$26+$Q$27*(1-$A$26)+$Q$28+$Q$29)*G$26*1000+($D35)*1000*$Q$25*$A$30*$A$32*1000+$A$36*$A$30*$A$32*1000)*100 -> 98.274849 | H35: =($D35)*1000*$Q$25*$A$30*$A$32*1000/(($Q$26*$A$26+$Q$27*(1-$A$26)+$Q$28+$Q$29)*H$26*1000+($D35)*1000*$Q$25*$A$30*$A$32*1000+$A$36*$A$30*$A$32*1000)*100 -> 96.215858 | I35: =($D35)*1000*$Q$25*$A$30*$A$32*1000/(($Q$26*$A$26+$Q$27*(1-$A$26)+$Q$28+$Q$29)*I$26*1000+($D35)*1000*$Q$25*$A$30*$A$32*1000+$A$36*$A$30*$A$32*1000)*100 -> 94.241374 | J35: =($D35)*1000*$Q$25*$A$30*$A$32*1000/(($Q$26*$A$26+$Q$27*(1-$A$26)+$Q$28+$Q$29)*J$26*1000+($D35)*1000*$Q$25*$A$30*$A$32*1000+$A$36*$A$30*$A$32*1000)*100 -> 92.346299 | K35: =($D35)*1000*$Q$25*$A$30*$A$32*1000/(($Q$26*$A$26+$Q$27*(1-$A$26)+$Q$28+$Q$29)*K$26*1000+($D35)*1000*$Q$25*$A$30*$A$32*1000+$A$36*$A$30*$A$32*1000)*100 -> 90.525937 | L35: =($D35)*1000*$Q$25*$A$30*$A$32*1000/(($Q$26*$A$26+$Q$27*(1-$A$26)+$Q$28+$Q$29)*L$26*1000+($D35)*1000*$Q$25*$A$30*$A$32*1000+$A$36*$A$30*$A$32*1000)*100 -> 88.775954 | ... N35: =($D35)*1000*$Q$25*$A$30*$A$32*1000/(($Q$26*$A$26+$Q$27*(1-$A$26)+$Q$28+$Q$29)*N$26*1000+($D35)*1000*$Q$25*$A$30*$A$32*1000+$A$36*$A$30*$A$32*1000)*100 -> 85.47141
A36: 0.1 | C36: 25 | D36: =C36*$A$15/1000 -> 6.25 | E36: =($D36)*1000*$Q$25*$A$30*$A$32*1000/(($Q$26*$A$26+$Q$27*(1-$A$26)+$Q$28+$Q$29)*E$26*1000+($D36)*1000*$Q$25*$A$30*$A$32*1000+$A$36*$A$30*$A$32*1000)*100 -> 99.383391 | F36: =($D36)*1000*$Q$25*$A$30*$A$32*1000/(($Q$26*$A$26+$Q$27*(1-$A$26)+$Q$28+$Q$29)*F$26*1000+($D36)*1000*$Q$25*$A$30*$A$32*1000+$A$36*$A$30*$A$32*1000)*100 -> 99.040456 | G36: =($D36)*1000*$Q$25*$A$30*$A$32*1000/(($Q$26*$A$26+$Q$27*(1-$A$26)+$Q$28+$Q$29)*G$26*1000+($D36)*1000*$Q$25*$A$30*$A$32*1000+$A$36*$A$30*$A$32*1000)*100 -> 98.615101 | H36: =($D36)*1000*$Q$25*$A$30*$A$32*1000/(($Q$26*$A$26+$Q$27*(1-$A$26)+$Q$28+$Q$29)*H$26*1000+($D36)*1000*$Q$25*$A$30*$A$32*1000+$A$36*$A$30*$A$32*1000)*100 -> 96.9496 | I36: =($D36)*1000*$Q$25*$A$30*$A$32*1000/(($Q$26*$A$26+$Q$27*(1-$A$26)+$Q$28+$Q$29)*I$26*1000+($D36)*1000*$Q$25*$A$30*$A$32*1000+$A$36*$A$30*$A$32*1000)*100 -> 95.339422 | J36: =($D36)*1000*$Q$25*$A$30*$A$32*1000/(($Q$26*$A$26+$Q$27*(1-$A$26)+$Q$28+$Q$29)*J$26*1000+($D36)*1000*$Q$25*$A$30*$A$32*1000+$A$36*$A$30*$A$32*1000)*100 -> 93.781856 | K36: =($D36)*1000*$Q$25*$A$30*$A$32*1000/(($Q$26*$A$26+$Q$27*(1-$A$26)+$Q$28+$Q$29)*K$26*1000+($D36)*1000*$Q$25*$A$30*$A$32*1000+$A$36*$A$30*$A$32*1000)*100 -> 92.274363 | L36: =($D36)*1000*$Q$25*$A$30*$A$32*1000/(($Q$26*$A$26+$Q$27*(1-$A$26)+$Q$28+$Q$29)*L$26*1000+($D36)*1000*$Q$25*$A$30*$A$32*1000+$A$36*$A$30*$A$32*1000)*100 -> 90.814568 | ... N36: =($D36)*1000*$Q$25*$A$30*$A$32*1000/(($Q$26*$A$26+$Q$27*(1-$A$26)+$Q$28+$Q$29)*N$26*1000+($D36)*1000*$Q$25*$A$30*$A$32*1000+$A$36*$A$30*$A$32*1000)*100 -> 88.029293
A37: Sand dosage (g/m2) | C37: 30 | D37: =C37*$A$15/1000 -> 7.5 | E37: =($D37)*1000*$Q$25*$A$30*$A$32*1000/(($Q$26*$A$26+$Q$27*(1-$A$26)+$Q$28+$Q$29)*E$26*1000+($D37)*1000*$Q$25*$A$30*$A$32*1000+$A$36*$A$30*$A$32*1000)*100 -> 99.48563 | F37: =($D37)*1000*$Q$25*$A$30*$A$32*1000/(($Q$26*$A$26+$Q$27*(1-$A$26)+$Q$28+$Q$29)*F$26*1000+($D37)*1000*$Q$25*$A$30*$A$32*1000+$A$36*$A$30*$A$32*1000)*100 -> 99.199099 | G37: =($D37)*1000*$Q$25*$A$30*$A$32*1000/(($Q$26*$A$26+$Q$27*(1-$A$26)+$Q$28+$Q$29)*G$26*1000+($D37)*1000*$Q$25*$A$30*$A$32*1000+$A$36*$A$30*$A$32*1000)*100 -> 98.843248 | H37: =($D37)*1000*$Q$25*$A$30*$A$32*1000/(($Q$26*$A$26+$Q$27*(1-$A$26)+$Q$28+$Q$29)*H$26*1000+($D37)*1000*$Q$25*$A$30*$A$32*1000+$A$36*$A$30*$A$32*1000)*100 -> 97.445011 | I37: =($D37)*1000*$Q$25*$A$30*$A$32*1000/(($Q$26*$A$26+$Q$27*(1-$A$26)+$Q$28+$Q$29)*I$26*1000+($D37)*1000*$Q$25*$A$30*$A$32*1000+$A$36*$A$30*$A$32*1000)*100 -> 96.085781 | J37: =($D37)*1000*$Q$25*$A$30*$A$32*1000/(($Q$26*$A$26+$Q$27*(1-$A$26)+$Q$28+$Q$29)*J$26*1000+($D37)*1000*$Q$25*$A$30*$A$32*1000+$A$36*$A$30*$A$32*1000)*100 -> 94.763949 | K37: =($D37)*1000*$Q$25*$A$30*$A$32*1000/(($Q$26*$A$26+$Q$27*(1-$A$26)+$Q$28+$Q$29)*K$26*1000+($D37)*1000*$Q$25*$A$30*$A$32*1000+$A$36*$A$30*$A$32*1000)*100 -> 93.477991 | L37: =($D37)*1000*$Q$25*$A$30*$A$32*1000/(($Q$26*$A$26+$Q$27*(1-$A$26)+$Q$28+$Q$29)*L$26*1000+($D37)*1000*$Q$25*$A$30*$A$32*1000+$A$36*$A$30*$A$32*1000)*100 -> 92.226468 | ... N37: =($D37)*1000*$Q$25*$A$30*$A$32*1000/(($Q$26*$A$26+$Q$27*(1-$A$26)+$Q$28+$Q$29)*N$26*1000+($D37)*1000*$Q$25*$A$30*$A$32*1000+$A$36*$A$30*$A$32*1000)*100 -> 89.821334
A38: 250 | C38: 35 | D38: =C38*$A$15/1000 -> 8.75 | E38: =($D38)*1000*$Q$25*$A$30*$A$32*1000/(($Q$26*$A$26+$Q$27*(1-$A$26)+$Q$28+$Q$29)*E$26*1000+($D38)*1000*$Q$25*$A$30*$A$32*1000+$A$36*$A$30*$A$32*1000)*100 -> 99.558788 | F38: =($D38)*1000*$Q$25*$A$30*$A$32*1000/(($Q$26*$A$26+$Q$27*(1-$A$26)+$Q$28+$Q$29)*F$26*1000+($D38)*1000*$Q$25*$A$30*$A$32*1000+$A$36*$A$30*$A$32*1000)*100 -> 99.312727 | G38: =($D38)*1000*$Q$25*$A$30*$A$32*1000/(($Q$26*$A$26+$Q$27*(1-$A$26)+$Q$28+$Q$29)*G$26*1000+($D38)*1000*$Q$25*$A$30*$A$32*1000+$A$36*$A$30*$A$32*1000)*100 -> 99.006857 | H38: =($D38)*1000*$Q$25*$A$30*$A$32*1000/(($Q$26*$A$26+$Q$27*(1-$A$26)+$Q$28+$Q$29)*H$26*1000+($D38)*1000*$Q$25*$A$30*$A$32*1000+$A$36*$A$30*$A$32*1000)*100 -> 97.801987 | I38: =($D38)*1000*$Q$25*$A$30*$A$32*1000/(($Q$26*$A$26+$Q$27*(1-$A$26)+$Q$28+$Q$29)*I$26*1000+($D38)*1000*$Q$25*$A$30*$A$32*1000+$A$36*$A$30*$A$32*1000)*100 -> 96.626089 | J38: =($D38)*1000*$Q$25*$A$30*$A$32*1000/(($Q$26*$A$26+$Q$27*(1-$A$26)+$Q$28+$Q$29)*J$26*1000+($D38)*1000*$Q$25*$A$30*$A$32*1000+$A$36*$A$30*$A$32*1000)*100 -> 95.478132 | K38: =($D38)*1000*$Q$25*$A$30*$A$32*1000/(($Q$26*$A$26+$Q$27*(1-$A$26)+$Q$28+$Q$29)*K$26*1000+($D38)*1000*$Q$25*$A$30*$A$32*1000+$A$36*$A$30*$A$32*1000)*100 -> 94.357131 | L38: =($D38)*1000*$Q$25*$A$30*$A$32*1000/(($Q$26*$A$26+$Q$27*(1-$A$26)+$Q$28+$Q$29)*L$26*1000+($D38)*1000*$Q$25*$A$30*$A$32*1000+$A$36*$A$30*$A$32*1000)*100 -> 93.262148 | ... N38: =($D38)*1000*$Q$25*$A$30*$A$32*1000/(($Q$26*$A$26+$Q$27*(1-$A$26)+$Q$28+$Q$29)*N$26*1000+($D38)*1000*$Q$25*$A$30*$A$32*1000+$A$36*$A$30*$A$32*1000)*100 -> 91.146694
A39: Traffic speed (km/h) | C39: 40 | D39: =C39*$A$15/1000 -> 10 | E39: =($D39)*1000*$Q$25*$A$30*$A$32*1000/(($Q$26*$A$26+$Q$27*(1-$A$26)+$Q$28+$Q$29)*E$26*1000+($D39)*1000*$Q$25*$A$30*$A$32*1000+$A$36*$A$30*$A$32*1000)*100 -> 99.613726 | F39: =($D39)*1000*$Q$25*$A$30*$A$32*1000/(($Q$26*$A$26+$Q$27*(1-$A$26)+$Q$28+$Q$29)*F$26*1000+($D39)*1000*$Q$25*$A$30*$A$32*1000+$A$36*$A$30*$A$32*1000)*100 -> 99.398119 | G39: =($D39)*1000*$Q$25*$A$30*$A$32*1000/(($Q$26*$A$26+$Q$27*(1-$A$26)+$Q$28+$Q$29)*G$26*1000+($D39)*1000*$Q$25*$A$30*$A$32*1000+$A$36*$A$30*$A$32*1000)*100 -> 99.12992 | H39: =($D39)*1000*$Q$25*$A$30*$A$32*1000/(($Q$26*$A$26+$Q$27*(1-$A$26)+$Q$28+$Q$29)*H$26*1000+($D39)*1000*$Q$25*$A$30*$A$32*1000+$A$36*$A$30*$A$32*1000)*100 -> 98.071439 | I39: =($D39)*1000*$Q$25*$A$30*$A$32*1000/(($Q$26*$A$26+$Q$27*(1-$A$26)+$Q$28+$Q$29)*I$26*1000+($D39)*1000*$Q$25*$A$30*$A$32*1000+$A$36*$A$30*$A$32*1000)*100 -> 97.035325 | J39: =($D39)*1000*$Q$25*$A$30*$A$32*1000/(($Q$26*$A$26+$Q$27*(1-$A$26)+$Q$28+$Q$29)*J$26*1000+($D39)*1000*$Q$25*$A$30*$A$32*1000+$A$36*$A$30*$A$32*1000)*100 -> 96.020874 | K39: =($D39)*1000*$Q$25*$A$30*$A$32*1000/(($Q$26*$A$26+$Q$27*(1-$A$26)+$Q$28+$Q$29)*K$26*1000+($D39)*1000*$Q$25*$A$30*$A$32*1000+$A$36*$A$30*$A$32*1000)*100 -> 95.027415 | L39: =($D39)*1000*$Q$25*$A$30*$A$32*1000/(($Q$26*$A$26+$Q$27*(1-$A$26)+$Q$28+$Q$29)*L$26*1000+($D39)*1000*$Q$25*$A$30*$A$32*1000+$A$36*$A$30*$A$32*1000)*100 -> 94.054303 | ... N39: =($D39)*1000*$Q$25*$A$30*$A$32*1000/(($Q$26*$A$26+$Q$27*(1-$A$26)+$Q$28+$Q$29)*N$26*1000+($D39)*1000*$Q$25*$A$30*$A$32*1000+$A$36*$A$30*$A$32*1000)*100 -> 92.166669
A40: 46 | C40: 45 | D40: =C40*$A$15/1000 -> 11.25 | E40: =($D40)*1000*$Q$25*$A$30*$A$32*1000/(($Q$26*$A$26+$Q$27*(1-$A$26)+$Q$28+$Q$29)*E$26*1000+($D40)*1000*$Q$25*$A$30*$A$32*1000+$A$36*$A$30*$A$32*1000)*100 -> 99.656498 | F40: =($D40)*1000*$Q$25*$A$30*$A$32*1000/(($Q$26*$A$26+$Q$27*(1-$A$26)+$Q$28+$Q$29)*F$26*1000+($D40)*1000*$Q$25*$A$30*$A$32*1000+$A$36*$A$30*$A$32*1000)*100 -> 99.464637 | G40: =($D40)*1000*$Q$25*$A$30*$A$32*1000/(($Q$26*$A$26+$Q$27*(1-$A$26)+$Q$28+$Q$29)*G$26*1000+($D40)*1000*$Q$25*$A$30*$A$32*1000+$A$36*$A$30*$A$32*1000)*100 -> 99.225847 | H40: =($D40)*1000*$Q$25*$A$30*$A$32*1000/(($Q$26*$A$26+$Q$27*(1-$A$26)+$Q$28+$Q$29)*H$26*1000+($D40)*1000*$Q$25*$A$30*$A$32*1000+$A$36*$A$30*$A$32*1000)*100 -> 98.282043 | I40: =($D40)*1000*$Q$25*$A$30*$A$32*1000/(($Q$26*$A$26+$Q$27*(1-$A$26)+$Q$28+$Q$29)*I$26*1000+($D40)*1000*$Q$25*$A$30*$A$32*1000+$A$36*$A$30*$A$32*1000)*100 -> 97.356024 | J40: =($D40)*1000*$Q$25*$A$30*$A$32*1000/(($Q$26*$A$26+$Q$27*(1-$A$26)+$Q$28+$Q$29)*J$26*1000+($D40)*1000*$Q$25*$A$30*$A$32*1000+$A$36*$A$30*$A$32*1000)*100 -> 96.447292 | K40: =($D40)*1000*$Q$25*$A$30*$A$32*1000/(($Q$26*$A$26+$Q$27*(1-$A$26)+$Q$28+$Q$29)*K$26*1000+($D40)*1000*$Q$25*$A$30*$A$32*1000+$A$36*$A$30*$A$32*1000)*100 -> 95.555368 | L40: =($D40)*1000*$Q$25*$A$30*$A$32*1000/(($Q$26*$A$26+$Q$27*(1-$A$26)+$Q$28+$Q$29)*L$26*1000+($D40)*1000*$Q$25*$A$30*$A$32*1000+$A$36*$A$30*$A$32*1000)*100 -> 94.679789 | ... N40: =($D40)*1000*$Q$25*$A$30*$A$32*1000/(($Q$26*$A$26+$Q$27*(1-$A$26)+$Q$28+$Q$29)*N$26*1000+($D40)*1000*$Q$25*$A$30*$A$32*1000+$A$36*$A$30*$A$32*1000)*100 -> 92.975903
A41: Road wear scaling (hpave) | C41: 50 | D41: =C41*$A$15/1000 -> 12.5 | E41: =($D41)*1000*$Q$25*$A$30*$A$32*1000/(($Q$26*$A$26+$Q$27*(1-$A$26)+$Q$28+$Q$29)*E$26*1000+($D41)*1000*$Q$25*$A$30*$A$32*1000+$A$36*$A$30*$A$32*1000)*100 -> 99.690742 | F41: =($D41)*1000*$Q$25*$A$30*$A$32*1000/(($Q$26*$A$26+$Q$27*(1-$A$26)+$Q$28+$Q$29)*F$26*1000+($D41)*1000*$Q$25*$A$30*$A$32*1000+$A$36*$A$30*$A$32*1000)*100 -> 99.517915 | G41: =($D41)*1000*$Q$25*$A$30*$A$32*1000/(($Q$26*$A$26+$Q$27*(1-$A$26)+$Q$28+$Q$29)*G$26*1000+($D41)*1000*$Q$25*$A$30*$A$32*1000+$A$36*$A$30*$A$32*1000)*100 -> 99.302722 | H41: =($D41)*1000*$Q$25*$A$30*$A$32*1000/(($Q$26*$A$26+$Q$27*(1-$A$26)+$Q$28+$Q$29)*H$26*1000+($D41)*1000*$Q$25*$A$30*$A$32*1000+$A$36*$A$30*$A$32*1000)*100 -> 98.451178 | I41: =($D41)*1000*$Q$25*$A$30*$A$32*1000/(($Q$26*$A$26+$Q$27*(1-$A$26)+$Q$28+$Q$29)*I$26*1000+($D41)*1000*$Q$25*$A$30*$A$32*1000+$A$36*$A$30*$A$32*1000)*100 -> 97.614113 | J41: =($D41)*1000*$Q$25*$A$30*$A$32*1000/(($Q$26*$A$26+$Q$27*(1-$A$26)+$Q$28+$Q$29)*J$26*1000+($D41)*1000*$Q$25*$A$30*$A$32*1000+$A$36*$A$30*$A$32*1000)*100 -> 96.791163 | K41: =($D41)*1000*$Q$25*$A$30*$A$32*1000/(($Q$26*$A$26+$Q$27*(1-$A$26)+$Q$28+$Q$29)*K$26*1000+($D41)*1000*$Q$25*$A$30*$A$32*1000+$A$36*$A$30*$A$32*1000)*100 -> 95.981972 | L41: =($D41)*1000*$Q$25*$A$30*$A$32*1000/(($Q$26*$A$26+$Q$27*(1-$A$26)+$Q$28+$Q$29)*L$26*1000+($D41)*1000*$Q$25*$A$30*$A$32*1000+$A$36*$A$30*$A$32*1000)*100 -> 95.1862 | ... N41: =($D41)*1000*$Q$25*$A$30*$A$32*1000/(($Q$26*$A$26+$Q$27*(1-$A$26)+$Q$28+$Q$29)*N$26*1000+($D41)*1000*$Q$25*$A$30*$A$32*1000+$A$36*$A$30*$A$32*1000)*100 -> 93.633595
A42: 1 | C42: 55 | D42: =C42*$A$15/1000 -> 13.75 | E42: =($D42)*1000*$Q$25*$A$30*$A$32*1000/(($Q$26*$A$26+$Q$27*(1-$A$26)+$Q$28+$Q$29)*E$26*1000+($D42)*1000*$Q$25*$A$30*$A$32*1000+$A$36*$A$30*$A$32*1000)*100 -> 99.718777 | F42: =($D42)*1000*$Q$25*$A$30*$A$32*1000/(($Q$26*$A$26+$Q$27*(1-$A$26)+$Q$28+$Q$29)*F$26*1000+($D42)*1000*$Q$25*$A$30*$A$32*1000+$A$36*$A$30*$A$32*1000)*100 -> 99.561549 | G42: =($D42)*1000*$Q$25*$A$30*$A$32*1000/(($Q$26*$A$26+$Q$27*(1-$A$26)+$Q$28+$Q$29)*G$26*1000+($D42)*1000*$Q$25*$A$30*$A$32*1000+$A$36*$A$30*$A$32*1000)*100 -> 99.365709 | H42: =($D42)*1000*$Q$25*$A$30*$A$32*1000/(($Q$26*$A$26+$Q$27*(1-$A$26)+$Q$28+$Q$29)*H$26*1000+($D42)*1000*$Q$25*$A$30*$A$32*1000+$A$36*$A$30*$A$32*1000)*100 -> 98.589994 | I42: =($D42)*1000*$Q$25*$A$30*$A$32*1000/(($Q$26*$A$26+$Q$27*(1-$A$26)+$Q$28+$Q$29)*I$26*1000+($D42)*1000*$Q$25*$A$30*$A$32*1000+$A$36*$A$30*$A$32*1000)*100 -> 97.826297 | J42: =($D42)*1000*$Q$25*$A$30*$A$32*1000/(($Q$26*$A$26+$Q$27*(1-$A$26)+$Q$28+$Q$29)*J$26*1000+($D42)*1000*$Q$25*$A$30*$A$32*1000+$A$36*$A$30*$A$32*1000)*100 -> 97.074341 | K42: =($D42)*1000*$Q$25*$A$30*$A$32*1000/(($Q$26*$A$26+$Q$27*(1-$A$26)+$Q$28+$Q$29)*K$26*1000+($D42)*1000*$Q$25*$A$30*$A$32*1000+$A$36*$A$30*$A$32*1000)*100 -> 96.333856 | L42: =($D42)*1000*$Q$25*$A$30*$A$32*1000/(($Q$26*$A$26+$Q$27*(1-$A$26)+$Q$28+$Q$29)*L$26*1000+($D42)*1000*$Q$25*$A$30*$A$32*1000+$A$36*$A$30*$A$32*1000)*100 -> 95.604583 | ... N42: =($D42)*1000*$Q$25*$A$30*$A$32*1000/(($Q$26*$A$26+$Q$27*(1-$A$26)+$Q$28+$Q$29)*N$26*1000+($D42)*1000*$Q$25*$A$30*$A$32*1000+$A$36*$A$30*$A$32*1000)*100 -> 94.178667
A45: Difference NORTRIP - EMEP/EEA | E45: =E28-E5 -> 3.0632522 | F45: =F28-F5 -> 11.729088 | G45: =G28-G5 -> 17.67017 | H45: =H28-H5 -> 23.268523 | I45: =I28-I5 -> 21.964566 | J45: =J28-J5 -> 19.845655 | K45: =K28-K5 -> 17.850854 | L45: =L28-L5 -> 16.128893 | ... N45: =N28-N5 -> 13.431459
E46: =E29-E6 -> 1.7894097 | F46: =F29-F6 -> 7.7003612 | G46: =G29-G6 -> 12.989823 | H46: =H29-H6 -> 22.483676 | I46: =I29-I6 -> 24.622857 | J46: =J29-J6 -> 24.485542 | K46: =K29-K6 -> 23.567054 | L46: =L29-L6 -> 22.399539 | ... N46: =N29-N6 -> 20.026014
...

Sheet Parameters_NORTRIP
A1: NORTRIP model parameters
A3: ROAD DUST SUB-MODEL PARAMETERS
A4: Road wear
A5: W0,roadwear (g km-1 veh-1) | B5: Studded tyres (st) | C5: Winter tyres (wi) | D5: Summer tyres (su)
A6: Heavy (he) | B6: 14.4 | C6: 0.36 | D6: 0.36
A7: Light (li) | B7: 2.88 | C7: 0.072 | D7: 0.072
A8: Parameters for speed dependence | B8: a1 | C8: a2 | D8: a3 | E8: Vref,roadwear | F8: Vmin,roadwear
A9: W=W0*(a1+a2*(max[V,Vmin]/Vref)a3) | B9: 0 | C9: 1 | D9: 1 | E9: 70 | F9: 30
A10: Tyre wear
A11: W0,tirewear (g km-1 veh-1) | B11: Studded tyres (st) | C11: Winter tyres (wi) | D11: Summer tyres (su)
A12: Heavy (he) | B12: 0.5 | C12: 0.5 | D12: 0.5
A13: Light (li) | B13: 0.1 | C13: 0.1 | D13: 0.1
A14: Parameters for speed dependence | B14: a1 | C14: a2 | D14: a3 | E14: Vref,tyrewear | F14: Vmin,tyrewear
A15: W=W0*(a1+a2*(max[V,Vmin]/Vref)a3) | B15: 0 | C15: 1 | D15: 1 | E15: 70 | F15: 30
A16: Brake wear
A17: W0,brakewear (g km-1 veh-1) | B17: Studded tyres (st) | C17: Winter tyres (wi) | D17: Summer tyres (su)
A18: Heavy (he) | B18: 0.05 | C18: 0.05 | D18: 0.05
A19: Light (li) | B19: 0.01 | C19: 0.01 | D19: 0.01
A20: Parameters for speed dependence | B20: a1 | C20: a2 | D20: a3 | E20: Vref,brakewear | F20: Vmin,brakewear
A21: W=W0*(a1+a2*(max[V,Vmin]/Vref)a3) | B21: 1 | C21: -0.75 | D21: 1 | E21: 120 | F21: 30
A22: Snow depth wear threshold
A23: Parameter | B23: Value
A24: sroadwear,thresh (mm w.e.) | B24: 5
A25: Pavement type scaling factor
A26: Number of pavement types | B26: 10
A27: Index(p) | B27: Name | C27: hpave (p)
A28: 1 | B28: NBM19_SS11 | C28: 1
A29: 2 | B29: NBM14_SS11 | C29: 2.9
A30: 3 | B30: NBM10_SS11 | C30: 2.32
A31: 4 | B31: NBM7_SS11 | C31: 1.9
A32: 5 | B32: NB_sletta | C32: 1
A33: 6 | B33: HCAB_before_2008 | C33: 4
A34: 7 | B34: Runeberg | C34: 1
A35: 8 | B35: HCAB_after_2008 | C35: 2
A36: 9 | B36: Stavanger | C36: 1
A37: 10 | B37: Finish/Honrnsgatan | C37: 0.98
A38: Driving cycle scaling factor
A39: Number of driving cycle types | B39: 4
A40: Index(d) | B40: Name | C40: hdrivingcycle (d)
A41: 1 | B41: Reference | C41: 1
...

Sheet Parameters_EMEP-EEA
A1: NORTRIP model parameters with EMEP/EEA handbook wear rates and fractions
A3: ROAD DUST SUB-MODEL PARAMETERS
A4: Road wear
A5: W0,roadwear (g km-1 veh-1) | B5: Studded tyres (st) | C5: Winter tyres (wi) | D5: Summer tyres (su)
A6: Heavy (he) | B6: 14.4 | C6: 0.076 | D6: 0.076
A7: Light (li) | B7: 2.88 | C7: 0.015 | D7: 0.015
A8: Parameters for speed dependence | B8: a1 | C8: a2 | D8: a3 | E8: Vref,roadwear | F8: Vmin,roadwear
A9: W=W0*(a1+a2*(max[V,Vmin]/Vref)a3) | B9: 0 | C9: 1 | D9: 1 | E9: 70 | F9: 30
A10: Tyre wear
A11: W0,tirewear (g km-1 veh-1) | B11: Studded tyres (st) | C11: Winter tyres (wi) | D11: Summer tyres (su)
A12: Heavy (he) | B12: 0.039 | C12: 0.039 | D12: 0.039
A13: Light (li) | B13: 0.011 | C13: 0.011 | D13: 0.011
A14: Parameters for speed dependence | B14: a1 | C14: a2 | D14: a3 | E14: Vref,tyrewear | F14: Vmin,tyrewear
A15: W=W0*(a1+a2*(max[V,Vmin]/Vref)a3) | B15: 0 | C15: 1 | D15: 1 | E15: 70 | F15: 30
A16: Brake wear
A17: W0,brakewear (g km-1 veh-1) | B17: Studded tyres (st) | C17: Winter tyres (wi) | D17: Summer tyres (su)
A18: Heavy (he) | B18: 0.022 | C18: 0.022 | D18: 0.022
A19: Light (li) | B19: 0.008 | C19: 0.008 | D19: 0.008
A20: Parameters for speed dependence | B20: a1 | C20: a2 | D20: a3 | E20: Vref,brakewear | F20: Vmin,brakewear
A21: W=W0*(a1+a2*(max[V,Vmin]/Vref)a3) | B21: 1 | C21: -0.75 | D21: 1 | E21: 120 | F21: 30
A22: Snow depth wear threshold
A23: Parameter | B23: Value
A24: sroadwear,thresh (mm w.e.) | B24: 5
A25: Pavement type scaling factor
A26: Number of pavement types | B26: 10
A27: Index(p) | B27: Name | C27: hpave (p)
A28: 1 | B28: NBM19_SS11 | C28: 1
A29: 2 | B29: NBM14_SS11 | C29: 2.9
A30: 3 | B30: NBM10_SS11 | C30: 2.32
A31: 4 | B31: NBM7_SS11 | C31: 1.9
A32: 5 | B32: NB_sletta | C32: 1
A33: 6 | B33: HCAB_before_2008 | C33: 4
A34: 7 | B34: Runeberg | C34: 1
A35: 8 | B35: HCAB_after_2008 | C35: 2
A36: 9 | B36: Stavanger | C36: 1
A37: 10 | B37: Finish/Honrnsgatan | C37: 0.98
A38: Driving cycle scaling factor
A39: Number of driving cycle types | B39: 4
A40: Index(d) | B40: Name | C40: hdrivingcycle (d)
A41: 1 | B41: Reference | C41: 1
...
